Workbook
Name _B1: '[1]252K444'!$H$21
Name _B2: '[1]252K444'!$J$21
Name _BL1: '[1]252K444'!$J$23
Name _BL2: '[1]252K444'!$D$24
Name _BL3: '[1]252K444'!$F$24
Name _BL4: '[1]252K444'!$H$24
Name _Bu1: #REF!
Name _Bu1: #REF!
Name _Bu2: #REF!
Name _Bu2: #REF!
Name _C: '[1]252K444'!$D$22
Name _E1: '[1]252K444'!$H$22
Name _E2: '[1]252K444'!$J$22
Name _Fu1: #REF!
Name _Fu1: #REF!
Name _Fu2: #REF!
Name _Fu2: #REF!
Name _H1: '[1]252K444'!$D$23
Name _H2: '[1]252K444'!$F$23
Name _H3: '[1]252K444'!$H$23
Name _Hg1: #REF!
Name _Hg1: #REF!
Name _Hg2: #REF!
Name _Hg2: #REF!
Name _hun1: [2]설계조건!#REF!
Name _hun1: [2]설계조건!#REF!
Name _hun2: [2]설계조건!#REF!
Name _hun2: [2]설계조건!#REF!
Name _Lg1: #REF!
Name _Lg1: #REF!
Name _Lg2: #REF!
Name _Lg2: #REF!
Name _pa1: #REF!
Name _pa1: #REF!
Name _pa2: #REF!
Name _pa2: #REF!
Name _qs1: [2]설계조건!#REF!
Name _qs1: [2]설계조건!#REF!
Name _qs12: [2]설계조건!#REF!
Name _qs12: [2]설계조건!#REF!
Name _qs2: [2]설계조건!#REF!
Name _qs2: [2]설계조건!#REF!
Name _qs22: [2]설계조건!#REF!
Name _qs22: [2]설계조건!#REF!
Name _T1: '[4]날개벽(좌,우=60도-4개)'!#REF!
Name _T1: '[4]날개벽(좌,우=60도-4개)'!#REF!
Name _T2: '[4]날개벽(좌,우=60도-4개)'!#REF!
Name _T2: '[4]날개벽(좌,우=60도-4개)'!#REF!
Name _Ted1: #REF!
Name _Ted1: #REF!
Name _Ts1: #REF!
Name _Ts1: #REF!
Name _Tu1: #REF!
Name _Tu1: #REF!
Name _Tu2: #REF!
Name _Tu2: #REF!
Name _wd1: [2]설계조건!#REF!
Name _wd1: [2]설계조건!#REF!
Name _wd2: [2]설계조건!#REF!
Name _wd2: [2]설계조건!#REF!

Sheet 공사갑지(총괄)
B1: 과 장 | D1: 팀 장 | F1: 심 사 자 | H1: 설 계 자 | J1: 설 계 | K1: 2020년 월 일 | L1: 결 재
J2: 심 사 | K2: 2020년 월 일 | L2: 월 일
B4: 설 계 내 역 서
C6: =+공종별집계표!A2 -> [ 업무시설 ]
C8: 구 분 | E8: 금 액 | K8: 비 고
C9: 총 공 사 비 | E9: =CONCATENATE(" 일금 ",NUMBERSTRING(I9,1),"원정") -> 일금 팔십억육천구백육십팔만구천원정 | I9: =ROUNDDOWN(I16,-3) -> 8069689000 | K9: 천원단위 절삭
C10: 도급비 | D10: 공 급 가 액 | E10: =CONCATENATE(" 일금 ",NUMBERSTRING(I10,1),"원정") -> 일금 칠십삼억삼천육백팔만일천이백칠십칠원정 | I10: =+'원가계산서 _조달청기준'!V33 -> 7336081277
D11: 부가가치세 | E11: =CONCATENATE(" 일금 ",NUMBERSTRING(I11,1),"원정") -> 일금 칠억삼천삼백육십만팔천일백이십칠원정 | I11: =+'원가계산서 _조달청기준'!V34 -> 733608127
D12: 분담금공사 | E12: =CONCATENATE(" 일금 ",NUMBERSTRING(I12,1),"원정") -> 일금 영원정 | I12: =+'원가계산서 _조달청기준'!V40 -> 0
D13: 하수분담금 | E13: =CONCATENATE(" 일금 ",NUMBERSTRING(I13,1),"원정") -> 일금 영원정 | I13: =+'원가계산서 _조달청기준'!V41 -> 0
D14: 전기사용전검사비 | E14: =CONCATENATE(" 일금 ",NUMBERSTRING(I14,1),"원정") -> 일금 영원정 | I14: =+'원가계산서 _조달청기준'!V43 -> 0
D15: 조달수수료 | E15: =CONCATENATE(" 일금 ",NUMBERSTRING(I15,1),"원정") -> 일금 영원정
D16: 계 | E16: =CONCATENATE(" 일금 ",NUMBERSTRING(I16,1),"원정") -> 일금 팔십억육천구백육십팔만구천사백사원정 | I16: =ROUNDDOWN(I11+I10+I12+I13+I14+I15,0) -> 8069689404
J21: =+I16-'원가계산서 _조달청기준'!V37 -> 0

Sheet 원가계산서 _조달청기준
B1: 공 사 원 가 계 산 서(건축) | Z1: 2020.09.08 공고분부터 적용
D2: =+공종별집계표!A2 -> [ 업무시설 ]
B3: 비 목 | E3: 합 계 | F3: 건축 | G3: 인테리어 | H3: 조경 | I3: 토목 | J3: 기계 | K3: 특수설비 | L3: 전기 | M3: 통신 | N3: 소방 | O3: 기계소방 | P3: 경관조명 | Q3: 구성비 | R3: 건축 | S3: 전기 | T3: 통신 | U3: 소방 | V3: 합계 | W3: 비 고
A4: A1 | B4: 순 공 사 원 가 | C4: 재 료 비 | D4: 직 접 재 료 비 | E4: =SUM(F4:P4) -> 2173427021 | F4: =+공종별집계표!F5 -> 2173427021 | V4: =SUM(F4:P4) -> 2173427021
A5: A2 | D5: 간 접 재 료 비 | E5: =SUM(F5:P5) -> 0 | V5: =SUM(F5:P5) -> 0
A6: A3 | D6: 작업설, 부산물(△) | E6: =SUM(F6:P6) -> 0 | V6: =SUM(F6:P6) -> 0
A7: AS | D7: [ 소 계 ] | E7: =SUM(F7:P7) -> 2173427021 | F7: =TRUNC(F4+F5-F6, 0) -> 2173427021 | G7: =TRUNC(G4+G5-G6, 0) -> 0 | H7: =TRUNC(H4+H5-H6, 0) -> 0 | I7: =TRUNC(I4+I5-I6, 0) -> 0 | J7: =TRUNC(J4+J5-J6, 0) -> 0 | K7: =TRUNC(K4+K5-K6, 0) -> 0 | L7: =TRUNC(L4+L5-L6, 0) -> 0 | M7: =TRUNC(M4+M5-M6, 0) -> 0 | ... P7: =TRUNC(P4+P5-P6, 0) -> 0 | V7: =SUM(F7:P7) -> 2173427021
A8: B1 | C8: 노 무 비 | D8: 직 접 노 무 비 | E8: =SUM(F8:P8) -> 2898047135 | F8: =+공종별집계표!H5 -> 2898047135 | V8: =SUM(F8:P8) -> 2898047135
A9: B2 | D9: 간 접 노 무 비 | E9: =SUM(F9:P9) -> 228945723 | F9: =TRUNC(F8*$R$9, 0) -> 228945723 | G9: =TRUNC(G8*$R$9, 0) -> 0 | H9: =TRUNC(H8*$R$9, 0) -> 0 | I9: =TRUNC(I8*$R$9, 0) -> 0 | J9: =TRUNC(J8*$R$9, 0) -> 0 | K9: =TRUNC(K8*$R$9, 0) -> 0 | L9: =TRUNC(L8*$S$9, 0) -> 0 | M9: =TRUNC(M8*$T$9, 0) -> 0 | N9: =TRUNC(N8*$U$9, 0) -> 0 | O9: =TRUNC(O8*$U$9, 0) -> 0 | P9: =TRUNC(P8*$U$9, 0) -> 0 | Q9: 직접노무비 | R9: 0.079 | S9: 0.073 | T9: 0.073 | U9: =+R9 -> 0.079 | V9: =SUM(F9:P9) -> 228945723
A10: BS | D10: [ 소 계 ] | E10: =SUM(F10:P10) -> 3126992858 | F10: =TRUNC(F8+F9, 0) -> 3126992858 | G10: =TRUNC(G8+G9, 0) -> 0 | H10: =TRUNC(H8+H9, 0) -> 0 | I10: =TRUNC(I8+I9, 0) -> 0 | J10: =TRUNC(J8+J9, 0) -> 0 | K10: =TRUNC(K8+K9, 0) -> 0 | L10: =TRUNC(L8+L9, 0) -> 0 | M10: =TRUNC(M8+M9, 0) -> 0 | ... P10: =TRUNC(P8+P9, 0) -> 0 | V10: =SUM(F10:P10) -> 3126992858
A11: C2 | C11: 경 비 | D11: 기 계 경 비 | E11: =SUM(F11:P11) -> 102238233 | F11: =+공종별집계표!J5 -> 102238233 | V11: =SUM(F11:P11) -> 102238233
A12: C4 | D12: 산 재 보 험 료 | E12: =SUM(F12:P12) -> 116636833 | F12: =TRUNC(F10*$R$12, 0) -> 116636833 | G12: =TRUNC(G10*$R$12, 0) -> 0 | H12: =TRUNC(H10*$R$12, 0) -> 0 | I12: =TRUNC(I10*$R$12, 0) -> 0 | J12: =TRUNC(J10*$R$12, 0) -> 0 | K12: =TRUNC(K10*$R$12, 0) -> 0 | L12: =TRUNC(L10*$S$12, 0) -> 0 | M12: =TRUNC(M10*$T$12, 0) -> 0 | N12: =TRUNC(N10*$U$12, 0) -> 0 | O12: =TRUNC(O10*$U$12, 0) -> 0 | P12: =TRUNC(P10*$U$12, 0) -> 0 | Q12: 노무비 | R12: 0.0373 | S12: 0.0373 | T12: 0.0373 | U12: =+R12 -> 0.0373 | V12: =SUM(F12:P12) -> 116636833 | W12: 모듡 건설공사에 적용
A13: C5 | D13: 고 용 보 험 료 | E13: =SUM(F13:P13) -> 27204837 | F13: =TRUNC(F10*$R$13, 0) -> 27204837 | G13: =TRUNC(G10*$R$13, 0) -> 0 | H13: =TRUNC(H10*$R$13, 0) -> 0 | I13: =TRUNC(I10*$R$13, 0) -> 0 | J13: =TRUNC(J10*$R$13, 0) -> 0 | K13: =TRUNC(K10*$R$13, 0) -> 0 | L13: =TRUNC(L10*$S$13, 0) -> 0 | M13: =TRUNC(M10*$T$13, 0) -> 0 | N13: =TRUNC(N10*$U$13, 0) -> 0 | O13: =TRUNC(O10*$U$13, 0) -> 0 | P13: =TRUNC(P10*$U$13, 0) -> 0 | Q13: 노무비 | R13: 0.0087 | S13: 0.0092 | T13: 0.0092 | U13: =+R13 -> 0.0087 | V13: =SUM(F13:P13) -> 27204837 | W13: 모든 건설공사에 적용
A14: C6 | D14: 국민 건강 보험료 | E14: =SUM(F14:P14) -> 96649871 | F14: =TRUNC(F8*$R$14, 0) -> 96649871 | G14: =TRUNC(G8*$R$14, 0) -> 0 | H14: =TRUNC(H8*$R$14, 0) -> 0 | I14: =TRUNC(I8*$R$14, 0) -> 0 | J14: =TRUNC(J8*$R$14, 0) -> 0 | K14: =TRUNC(K8*$R$14, 0) -> 0 | L14: =TRUNC(L8*$S$14, 0) -> 0 | M14: =TRUNC(M8*$T$14, 0) -> 0 | N14: =TRUNC(N8*$U$14, 0) -> 0 | O14: =TRUNC(O8*$U$14, 0) -> 0 | P14: =TRUNC(P8*$U$14, 0) -> 0 | Q14: 직접노무비 | R14: 0.03335 | S14: 0.03335 | T14: 0.03335 | U14: =+R14 -> 0.03335 | V14: =SUM(F14:P14) -> 96649871 | W14: 1개월이상 모든공사 적용
A15: C7 | D15: 국민 연금 보험료 | E15: =SUM(F15:P15) -> 130412121 | F15: =TRUNC(F8*$R$15, 0) -> 130412121 | G15: =TRUNC(G8*$R$15, 0) -> 0 | H15: =TRUNC(H8*$R$15, 0) -> 0 | I15: =TRUNC(I8*$R$15, 0) -> 0 | J15: =TRUNC(J8*$R$15, 0) -> 0 | L15: =TRUNC(L8*$S$15, 0) -> 0 | M15: =TRUNC(M8*$T$15, 0) -> 0 | N15: =TRUNC(N8*$U$15, 0) -> 0 | O15: =TRUNC(O8*$U$15, 0) -> 0 | P15: =TRUNC(P8*$U$15, 0) -> 0 | Q15: 직접노무비 | R15: 0.045 | S15: 0.045 | T15: 0.045 | U15: =+R15 -> 0.045 | V15: =SUM(F15:P15) -> 130412121 | W15: 1개월이상 모든공사 적용
A16: CB | D16: 노인장기요양보험료 | E16: =SUM(F16:P16) -> 9906611 | F16: =TRUNC(F14*$R$16, 0) -> 9906611 | G16: =TRUNC(G14*$R$16, 0) -> 0 | H16: =TRUNC(H14*$R$16, 0) -> 0 | I16: =TRUNC(I14*$R$16, 0) -> 0 | J16: =TRUNC(J14*$R$16, 0) -> 0 | L16: =TRUNC(L14*$S$16, 0) -> 0 | M16: =TRUNC(M14*$T$16, 0) -> 0 | N16: =TRUNC(N14*$U$16, 0) -> 0 | O16: =TRUNC(O14*$U$16, 0) -> 0 | P16: =TRUNC(P14*$U$16, 0) -> 0 | Q16: 건강보험료 | R16: 0.1025 | S16: 0.1025 | T16: 0.1025 | U16: =+R16 -> 0.1025 | V16: =SUM(F16:P16) -> 9906611 | W16: 1개월이상 모든공사 적용
A17: C8 | D17: 퇴직 공제 부금비 | E17: =SUM(F17:P17) -> 66655084 | F17: =TRUNC(F8*$R$17, 0) -> 66655084 | G17: =TRUNC(G8*$R$17, 0) -> 0 | H17: =TRUNC(H8*$R$17, 0) -> 0 | I17: =TRUNC(I8*$R$17, 0) -> 0 | J17: =TRUNC(J8*$R$17, 0) -> 0 | L17: =TRUNC(L8*$S$17, 0) -> 0 | M17: =TRUNC(M8*$T$17, 0) -> 0 | N17: =TRUNC(N8*$U$17, 0) -> 0 | O17: =TRUNC(O8*$U$17, 0) -> 0 | P17: =TRUNC(P8*$U$17, 0) -> 0 | Q17: 직접노무비 | R17: 0.023 | S17: 0.023 | T17: 0.023 | U17: =+R17 -> 0.023 | V17: =SUM(F17:P17) -> 66655084 | W17: 추정금액 1억원 이상 건설공사
A18: CA | D18: 산업안전보건관리비 | E18: =SUM(F18:P18) -> 94329419 | F18: =TRUNC((F7+F8)*$R$18, 0) -> 94329419 | G18: =TRUNC((G7+G8)*$R$18, 0) -> 0 | H18: =TRUNC((H7+H8)*$R$18, 0) -> 0 | I18: =TRUNC((I7+I8)*$R$18, 0) -> 0 | J18: =TRUNC((J7+J8)*$R$18, 0) -> 0 | L18: =TRUNC((L7+L8)*$S$18, 0) -> 0 | M18: =TRUNC((M7+M8)*$T$18, 0) -> 0 | N18: =TRUNC((N7+N8)*$U$18, 0) -> 0 | O18: =TRUNC((O7+O8+(O38)/1.1)*$U$18, 0) -> 0 | P18: =TRUNC((P7+P8+(P38)/1.1)*$S$18, 0) -> 0 | Q18: (재료+직노)*요율 | R18: 0.0186 | S18: 0.0197 | T18: 0.0197 | U18: =+R18 -> 0.0186 | V18: =SUM(F18:P18) -> 94329419 | W18: 총 공사금액 2천만원 이상 건설공사
A19: CH | D19: 환 경 보 전 비 | E19: =SUM(F19:P19) -> 25868561 | F19: =TRUNC((F7+F8+F11)*$R$19, 0) -> 25868561 | G19: =TRUNC((G7+G8+G11)*$R$19, 0) -> 0 | H19: =TRUNC((H7+H8+H11)*$R$19, 0) -> 0 | I19: =TRUNC((I7+I8+I11)*$R$19, 0) -> 0 | J19: =TRUNC((J7+J8+J11)*$R$19, 0) -> 0 | L19: =TRUNC((L7+L8+L11)*$S$19, 0) -> 0 | M19: =TRUNC((M7+M8+M11)*$T$19, 0) -> 0 | N19: =TRUNC((N7+N8+N11)*$U$19, 0) -> 0 | O19: =TRUNC((O7+O8+O11)*$S$19, 0) -> 0 | P19: =TRUNC((P7+P8+P11)*$S$19, 0) -> 0 | Q19: (재료+직노+기계경비) | R19: 0.005 | S19: 0 | T19: 0 | U19: 0 | V19: =SUM(F19:P19) -> 25868561 | W19: 전기,정보통신,소방시설, 문화재수리공사 제외
A20: CG | D20: 기 타 경 비 | E20: =SUM(F20:P20) -> 307424352 | F20: =TRUNC((F7+F10)*$R$20, 0) -> 307424352 | G20: =TRUNC((G7+G10)*$R$20, 0) -> 0 | H20: =TRUNC((H7+H10)*$R$20, 0) -> 0 | I20: =TRUNC((I7+I10)*$R$20, 0) -> 0 | J20: =TRUNC((J7+J10)*$R$20, 0) -> 0 | L20: =TRUNC((L7+L10)*$S$20, 0) -> 0 | M20: =TRUNC((M7+M10)*$T$20, 0) -> 0 | N20: =TRUNC((N7+N10)*$U$20, 0) -> 0 | O20: =TRUNC((O7+O10)*$U$20, 0) -> 0 | P20: =TRUNC((P7+P10)*$S$20, 0) -> 0 | Q20: (재료+노무비) | R20: 0.058 | S20: 0.084 | T20: 0.084 | U20: =+R20 -> 0.058 | V20: =SUM(F20:P20) -> 307424352
A21: CJ | D21: 공사이행보증수수료 | E21: =SUM(F21:P21) -> 0 | F21: =TRUNC((5600000+((F4+F8+F11)-14000000000)*0.0264%)*2)*0 -> 0 | G21: =TRUNC((5600000+((G4+G8+G11)-14000000000)*0.0264%)*2)*0 -> 0 | I21: =TRUNC((5600000+((I4+I8+I11)-14000000000)*0.0264%)*2)*0 -> 0 | J21: =TRUNC((5600000+((J4+J8+J11)-14000000000)*0.0264%)*2)*0 -> 0 | L21: =TRUNC((5600000+((L4+L8+L11)-14000000000)*0.0264%)*2)*0 -> 0 | Q21: [5.6백만원+(직접공사비-140억원) x 0.0264%] x 공기(년) | V21: =SUM(F21:P21) -> 0
A22: CK | D22: 하도급지급보증수수료 | E22: =SUM(F22:P22) -> 4190707 | F22: =TRUNC((F7+F8+F11)*$R$22, 0) -> 4190707 | G22: =TRUNC((G7+G8+G11)*$R$22, 0) -> 0 | H22: =TRUNC((H7+H8+H11)*$R$22, 0) -> 0 | I22: =TRUNC((I7+I8+I11)*$R$22, 0) -> 0 | J22: =TRUNC((J7+J8+J11)*$R$22, 0) -> 0 | L22: =TRUNC((L7+L8+L11)*$S$22, 0) -> 0 | M22: =TRUNC((M7+M8+M11)*$T$22, 0) -> 0 | N22: =TRUNC((N7+N8+N11)*$U$22, 0) -> 0 | O22: =TRUNC((O7+O8+O11)*$S$22, 0) -> 0 | P22: =TRUNC((P7+P8+P11)*$S$22, 0) -> 0 | Q22: (재료+직노+기계경비) | R22: 0.00081 | S22: 0 | T22: 0 | U22: 0 | V22: =SUM(F22:P22) -> 4190707
D23: 건설기계대여금지급보증수수료 | F23: =TRUNC((F7+F8+F11)*$R$23, 0) -> 3621598 | G23: =TRUNC((G7+G8+G11)*$R$23, 0) -> 0 | H23: =TRUNC((H7+H8+H11)*$R$23, 0) -> 0 | I23: =TRUNC((I7+I8+I11)*$R$23, 0) -> 0 | J23: =TRUNC((J7+J8+J11)*$R$23, 0) -> 0 | Q23: (재료+직노+기계경비) | R23: 0.0007 | S23: 0 | T23: 0 | U23: 0 | V23: =SUM(F23:P23) -> 3621598 | W23: 문화재 수리공사,전기,정보통신,소방시설 제외
A24: CS | D24: [ 소 계 ] | E24: =SUM(F24:P24) -> 985138227 | F24: =+SUM(F11:F23) -> 985138227 | G24: =+SUM(G11:G23) -> 0 | H24: =+SUM(H11:H23) -> 0 | I24: =+SUM(I11:I23) -> 0 | J24: =+SUM(J11:J23) -> 0 | K24: =TRUNC(K11+K12+K13+K14+K15+K17+K18+K16+K20+K19+K21+K22, 0) -> 0 | L24: =+SUM(L11:L23) -> 0 | M24: =+SUM(M11:M23) -> 0 | N24: =+SUM(N11:N23) -> 0 | O24: =TRUNC(O11+O12+O13+O14+O15+O17+O18+O16+O20+O19+O21+O22, 0) -> 0 | P24: =TRUNC(P11+P12+P13+P14+P15+P17+P18+P16+P20+P19+P21+P22, 0) -> 0 | V24: =SUM(F24:P24) -> 985138227
A25: S1 | B25: 계 | E25: =SUM(F25:P25) -> 6285558106 | F25: =TRUNC(F7+F10+F24, 0) -> 6285558106 | G25: =TRUNC(G7+G10+G24, 0) -> 0 | H25: =TRUNC(H7+H10+H24, 0) -> 0 | I25: =TRUNC(I7+I10+I24, 0) -> 0 | J25: =TRUNC(J7+J10+J24, 0) -> 0 | K25: =TRUNC(K7+K10+K24, 0) -> 0 | L25: =TRUNC(L7+L10+L24, 0) -> 0 | M25: =TRUNC(M7+M10+M24, 0) -> 0 | ... P25: =TRUNC(P7+P10+P24, 0) -> 0 | V25: =SUM(F25:P25) -> 6285558106
A26: D1 | B26: 일 반 관 리 비 | E26: =SUM(F26:P26) -> 377133486 | F26: =TRUNC(F25*$R$26, 0) -> 377133486 | G26: =TRUNC(G25*$R$26, 0) -> 0 | H26: =TRUNC(H25*$R$26, 0) -> 0 | I26: =TRUNC(I25*$R$26, 0) -> 0 | J26: =TRUNC(J25*$R$26, 0) -> 0 | K26: =TRUNC(K25*$R$26, 0) -> 0 | L26: =TRUNC(L25*$S$26, 0) -> 0 | M26: =TRUNC(M25*$S$26, 0) -> 0 | N26: =TRUNC(N25*$U$26, 0) -> 0 | O26: =TRUNC(O25*$U$26, 0) -> 0 | P26: =TRUNC(P25*$S$26, 0) -> 0 | Q26: 계 | R26: 0.06 | S26: 0.05 | T26: 0.05 | U26: =+R26 -> 0.06 | V26: =SUM(F26:P26) -> 377133486
A27: D2 | B27: 이 윤 | E27: =SUM(F27:P27) -> 673389685 | F27: =TRUNC((F10+F24+F26)*$R$27, 0) -> 673389685 | G27: =TRUNC((G10+G24+G26)*$R$27, 0) -> 0 | H27: =TRUNC((H10+H24+H26)*$R$27, 0) -> 0 | I27: =TRUNC((I10+I24+I26)*$R$27, 0) -> 0 | J27: =TRUNC((J10+J24+J26)*$R$27, 0) -> 0 | K27: =TRUNC((K10+K24+K26)*$R$27, 0) -> 0 | L27: =TRUNC((L10+L24+L26)*$S$27, 0) -> 0 | M27: =TRUNC((M10+M24+M26)*$T$27, 0) -> 0 | N27: =TRUNC((N10+N24+N26)*$U$27, 0) -> 0 | O27: =TRUNC((O10+O24+O26)*$U$27, 0) -> 0 | P27: =TRUNC((P10+P24+P26)*$S$27, 0) -> 0 | Q27: (노무+경비+일반관리) | R27: 0.15 | S27: 0.12 | T27: 0.12 | U27: =+R27 -> 0.15 | V27: =SUM(F27:P27) -> 673389685
A28: D3 | B28: 폐기물 처리비 | E28: =SUM(F28:P28) -> 0 | V28: =SUM(F28:P28) -> 0
A29: D6 | B29: 한 전 불 입 금 | E29: =SUM(F29:P29) -> 0 | V29: =SUM(F29:P29) -> 0
B30: 사 용 전 검 사 비 | E30: =SUM(F30:P30) -> 0 | V30: =SUM(F30:P30) -> 0
B31: T.A.B 공사 | V31: =SUM(F31:P31) -> 0
A32: D6 | B32: 지역난방인입분담금 | E32: =SUM(F32:P32) -> 0 | V32: =SUM(F32:P32) -> 0
A33: D9 | B33: 공 급 가 액 | E33: =SUM(F33:P33) -> 7336081277 | F33: =+ROUNDDOWN((F25+F26+F27+F28+F29+F30+F32),0) -> 7336081277 | H33: =+ROUNDDOWN((H25+H26+H27+H28+H29+H30+H32),0) -> 0 | I33: =+ROUNDDOWN((I25+I26+I27+I28+I29+I30+I32),0) -> 0 | J33: =+ROUNDDOWN((J25+J26+J27+J28+J29+J30+J32),0) -> 0 | K33: =+ROUNDDOWN((K25+K26+K27+K28+K29+K30+K32),-4) -> 0 | L33: =+ROUNDDOWN((L25+L26+L27+L28+L29+L30+L32),0) -> 0 | M33: =+ROUNDDOWN((M25+M26+M27+M28+M29+M30+M32),0)-0 -> 0 | N33: =+ROUNDDOWN((N25+N26+N27+N28+N29+N30+N32),0) -> 0 | O33: =+ROUNDDOWN((O25+O26+O27+O28+O29+O30+O32),-4) -> 0 | P33: =+ROUNDDOWN((P25+P26+P27+P28+P29+P30+P32),-4) -> 0 | V33: =SUM(F33:P33) -> 7336081277
A34: DB | B34: 부 가 가 치 세 | E34: =SUM(F34:P34) -> 733608127 | F34: =TRUNC(F33*$S$34, 0) -> 733608127 | G34: =TRUNC(G33*$R$34, 0) -> 0 | H34: =TRUNC(H33*$S$34, 0) -> 0 | I34: =TRUNC(I33*$S$34, 0) -> 0 | J34: =TRUNC(J33*$S$34, 0) -> 0 | K34: =TRUNC(K33*$R$34, 0) -> 0 | L34: =TRUNC(L33*$S$34, 0) -> 0 | M34: =TRUNC(M33*$S$34, 0) -> 0 | N34: =TRUNC(N33*$S$34, 0) -> 0 | O34: =TRUNC(O33*$S$34, 0) -> 0 | P34: =TRUNC(P33*$S$34, 0) -> 0 | Q34: 공급가액 | R34: 0.1 | S34: 0.1 | T34: 0.1 | U34: 0.1 | V34: =SUM(F34:P34) -> 733608127
B35: 매 입 세 | F35: =+F4*R35*W35 -> 0 | I35: =+I4*R35*W35 -> 0 | J35: =+J4*R35*W35 -> 0 | L35: =+L4*S35*W35 -> 0 | M35: =+M4*T35*W35 -> 0 | N35: =+N4*U35*W35 -> 0 | Q35: 직접재료비 | R35: 0.1 | S35: 0.1 | T35: 0.1 | U35: 0.1 | V35: =SUM(F35:P35) -> 0 | W35: 0
A36: D6 | B36: 한 전 불 입 금 | E36: =SUM(F36:P36) -> 0 | V36: =SUM(F36:P36) -> 0
A37: DH | B37: 도 급 액 | E37: =SUM(F37:P37) -> 8069689404 | F37: =TRUNC(F33+F34+F35+F36, 0) -> 8069689404 | G37: =TRUNC(G33+G34, 0) -> 0 | H37: =TRUNC(H33+H34, 0) -> 0 | I37: =TRUNC(I33+I34+I35+I36, 0) -> 0 | J37: =TRUNC(J33+J34+J35+J36, 0) -> 0 | K37: =TRUNC(K33+K34, 0) -> 0 | L37: =TRUNC(L33+L34+L35+L36, 0) -> 0 | M37: =TRUNC(M33+M34+M35+M36, 0) -> 0 | N37: =TRUNC(N33+N34+N35+N36, 0) -> 0 | O37: =TRUNC(O33+O34, 0) -> 0 | P37: =TRUNC(P33+P34, 0) -> 0 | V37: =SUM(F37:P37) -> 8069689404
A38: DJ | B38: 도급자 관급자재비 | E38: =SUM(F38:P38) -> 0 | V38: =SUM(F38:P38) -> 0
B39: 관급자 관급자재비 | E39: =SUM(F39:P39) -> 0 | V39: =SUM(F39:P39) -> 0
A40: DN | B40: 분 담 금 공 사 | E40: =SUM(F40:P40) -> 0 | V40: =SUM(F40:P40) -> 0
...

Sheet 개요
C1: 기준 | D1: 변경 | E1: 수량입력 | X1: 연면적 | Y1: 감리,감독 | Z1: 수급자 | AA1: 창고
A2: 대지면적 | C2: 1039 | D2: 1039 | R2: 공종별 내역서에서 공통가설과 연관 - I7, I8, I9 | X2: 100000000 | Y2: 80 | Z2: 100 | AA2: 180
A3: 대지둘레 | C3: 129 | D3: =+D2*12.42% -> 129.0438 | E3: 대지면적의 12.42% 적용(임의계산) | X3: 6000 | Y3: 46 | Z3: 60 | AA3: 130
A4: 건축면적 | C4: 615.54 | D4: =+D2*D8 -> 615.5036 | E4: 대지면적 * 건폐율 | S4: 1000M2이하 | T4: 3000M2이하 | U4: 6000M2이하 | V4: 6000M2초과 | X4: 3000 | Y4: 38 | Z4: 50 | AA4: 100
A5: 건물높이 | C5: 43.7 | D5: =+D4/D3*10 -> 47.697262 | E5: 건축면적/대지둘레(가중평균높이로 계산) | R5: 감리,감독 | S5: 18 | T5: 38 | U5: 46 | V5: 80 | X5: 1000 | Y5: 18 | Z5: 24 | AA5: 70
A6: 건물층수 | C6: 8 | D6: =+(D9*D2)/D4 -> 5.8492573 | E6: 용적율*대지면적 / 건축면적 (층변화없이 올라갈경우 - 지하층제외) | R6: 수급자 | S6: 24 | T6: 50 | U6: 60 | V6: 100
A7: 지역 및 지구 | C7: 준공업지역 | D7: 준공업지역 | R7: 창고 | S7: 70 | T7: 100 | U7: 130 | V7: 180
A8: 건폐율 | C8: 0.5924 | D8: 0.5924
A9: 용적율 | C9: 3.4651 | D9: 3.4651
A10: 연면적 | B10: 지하 | C10: =873.26+864.61 -> 1737.87 | D10: 1737.87
B11: 지상 | C11: =+C12-C10 -> 3652.61 | D11: =+D9*D2 -> 3600.2389 | E11: 대지면적 * 용적율
B12: 합계 | C12: 5390.48 | D12: =+D11+D10 -> 5338.1089
A13: 건물둘레 | C13: =+C4*16.9% -> 104.02626 | D13: =+D4*16.9% -> 104.02011 | E13: 건축면적의 16.9% 적용(임의계산)
A14: 옥탑면적 | C14: =7.3*9.3 -> 67.89 | D14: =0.125*D4 -> 76.93795 | E14: 옥탑면적은 건축면적의 1/8을 초과할수 없다
A15: 옥탑둘레 | C15: =+C11*1.11% -> 40.543971 | D15: =+D14*43.15% -> 33.198725 | E15: 옥탑면적의 43.15% 적용(임의계산)
A16: 지하둘레 | C16: =+C10*6.84% -> 118.87031 | D16: =+C16 -> 118.87031 | E16: 지하연면적의 6.84% 적용(임의계산)
A17: 외벽면적 | D17: =+D13*(E28*F28+E29*F29+E30*F30)/1000 +D15*E31*F31/1000 -> 4100.4984 | E17: =건물둘레*(지상 각층의 층고*수량)/1000+옥탑둘레*옥탑층의 층고*수량)/1000
A18: 외벽재료비율 | C18: 창호 | D18: 0.39
C19: 석재 | D19: 0.53
C20: 알루미늄쉬트 | D20: 0.08
C21: 합계 | D21: =+D18+D19+D20 -> 1
A22: 공기 | C22: 12 | D22: 12
A24: 층 | C24: 지하2층, 지상8층 | E24: (단위 : mm)
A25: 층고 | B25: 구분 | D25: 기준층고 | E25: 층고 | F25: 수량
B26: 지하 | C26: 최하층 | D26: 3200 | E26: 3200 | F26: 1
C27: 기준층 | D27: 3600 | E27: 3600 | F27: 1
B28: 지상 | C28: 1층 | D28: 6000 | E28: 6000 | F28: 1
C29: 2층 | D29: 5000 | E29: 5000 | F29: 1
C30: 기준층 | D30: 4500 | E30: 4500 | F30: 6
C31: 옥상층 | D31: 4450 | E31: 4450 | F31: 1
A32: 건물높이 | E32: =+E28*F28+E29*F29+E30*F30+E31*F31 -> 42450
F33: 5열과 비교하여 5열보다 높지 않게 정리
A34: 기본층고 | D34: (단위 : mm)
A35: 구분 | B35: 기준 | C35: 층고
A36: 업무시설 | B36: 3500 | C36: 3500
A37: 화장실 | B37: 3050 | C37: 3050
A38: 파라펫방수 | B38: 300 | C38: 300
A39: TOP SLAB 내림 | B39: 1000 | C39: 1000
A40: 화장실방수 | B40: 1200 | C40: 1200
A43: 지하/연면적 | B43: =$D$10 -> 1737.87 | C43: MAT기초 두께(mm) | D43: 1500 | E43: 합벽 여부( 0 or 1 ) | F43: 1 | G43: RAMP 여부( 0 or 1 ) | H43: 1 | J43: 기본 스판 모듈(X/Y) | K43: 6 | L43: 10.2
...

Sheet 공종별집계표
A1: 공 종 별 집 계 표
A2: [ 업무시설 ]
A3: 품 명 | B3: 규 격 | C3: 단위 | D3: 수량 | E3: 재 료 비 | G3: 노 무 비 | I3: 경 비 | K3: 합 계 | M3: 평당공사비 | N3: 비 고 | O3: 공종코드 | P3: 변수 | Q3: 상위공종 | R3: 공종구분 | S3: 공종레벨 | T3: 공종소계 | U3: 원가계산서 연결금액
E4: 단 가 | F4: 금 액 | G4: 단 가 | H4: 금 액 | I4: 단 가 | J4: 금 액 | K4: 단 가 | L4: 금 액 | M4: =+개요!D12*0.3025 -> 1614.7779
A5: 01 업무시설 | D5: 1 | E5: =F6+F7+F8+F9+F10+F11+F12+F13+F14+F15+F16+F17+F18+F19+F20 -> 2173427021 | F5: =E5*D5 -> 2173427021 | G5: =H6+H7+H8+H9+H10+H11+H12+H13+H14+H15+H16+H17+H18+H19+H20 -> 2898047135 | H5: =G5*D5 -> 2898047135 | I5: =J6+J7+J8+J9+J10+J11+J12+J13+J14+J15+J16+J17+J18+J19+J20 -> 102238233 | J5: =I5*D5 -> 102238233 | K5: =E5+G5+I5 -> 5173712389 | L5: =F5+H5+J5 -> 5173712389 | M5: =+L5/$M$4 -> 3203977.6 | O5: 01 | S5: 1
A6: 0101 공통 가설 공사 | D6: 1 | E6: =공종별내역서!N27 -> 0 | F6: =E6*D6 -> 0 | G6: =공종별내역서!P27 -> 0 | H6: =G6*D6 -> 0 | I6: =공종별내역서!R27 -> 43147375 | J6: =I6*D6 -> 43147375 | K6: =E6+G6+I6 -> 43147375 | L6: =F6+H6+J6 -> 43147375 | M6: =+L6/$M$4 -> 26720.315 | O6: 0101 | Q6: 01 | S6: 2
A7: 0102 가 설 공 사 | D7: 1 | E7: =공종별내역서!N51 -> 135951033 | F7: =E7*D7 -> 135951033 | G7: =공종별내역서!P51 -> 457860157 | H7: =G7*D7 -> 457860157 | I7: =공종별내역서!R51 -> 9882876 | J7: =I7*D7 -> 9882876 | K7: =E7+G7+I7 -> 603694066 | L7: =F7+H7+J7 -> 603694066 | M7: =+L7/$M$4 -> 373855.78 | O7: 0102 | Q7: 01 | S7: 2
A8: 0103 철근콘크리트공사 | D8: 1 | E8: =공종별내역서!N99 -> 890257458 | F8: =E8*D8 -> 890257458 | G8: =공종별내역서!P99 -> 1271528867 | H8: =G8*D8 -> 1271528867 | I8: =공종별내역서!R99 -> 29266939 | J8: =I8*D8 -> 29266939 | K8: =E8+G8+I8 -> 2191053264 | L8: =F8+H8+J8 -> 2191053264 | M8: =+L8/$M$4 -> 1356875.9 | O8: 0103 | Q8: 01 | S8: 2
A9: 0104 조 적 공 사 | D9: 1 | E9: =공종별내역서!N123 -> 822880 | F9: =E9*D9 -> 822880 | G9: =공종별내역서!P123 -> 3976463 | H9: =G9*D9 -> 3976463 | I9: =공종별내역서!R123 -> 77392 | J9: =I9*D9 -> 77392 | K9: =E9+G9+I9 -> 4876735 | L9: =F9+H9+J9 -> 4876735 | M9: =+L9/$M$4 -> 3020.0654 | O9: 0104 | Q9: 01 | S9: 2
A10: 0105 석 공 사 | D10: 1 | E10: =공종별내역서!N145 -> 180151939 | F10: =E10*D10 -> 180151939 | G10: =공종별내역서!P145 -> 307357495 | H10: =G10*D10 -> 307357495 | I10: =공종별내역서!R145 -> 7395947 | J10: =I10*D10 -> 7395947 | K10: =E10+G10+I10 -> 494905381 | L10: =F10+H10+J10 -> 494905381 | M10: =+L10/$M$4 -> 306485.1 | O10: 0105 | Q10: 01 | S10: 2
A11: 0106 타 일 공 사 | D11: 1 | E11: =공종별내역서!N169 -> 13136238 | F11: =E11*D11 -> 13136238 | G11: =공종별내역서!P169 -> 63492571 | H11: =G11*D11 -> 63492571 | I11: =공종별내역서!R169 -> 1584139 | J11: =I11*D11 -> 1584139 | K11: =E11+G11+I11 -> 78212948 | L11: =F11+H11+J11 -> 78212948 | M11: =+L11/$M$4 -> 48435.73 | O11: 0106 | Q11: 01 | S11: 2
A12: 0107 방 수 공 사 | D12: 1 | E12: =공종별내역서!N193 -> 55824509 | F12: =E12*D12 -> 55824509 | G12: =공종별내역서!P193 -> 199187696 | H12: =G12*D12 -> 199187696 | I12: =공종별내역서!R193 -> 549382 | J12: =I12*D12 -> 549382 | K12: =E12+G12+I12 -> 255561587 | L12: =F12+H12+J12 -> 255561587 | M12: =+L12/$M$4 -> 158264.23 | O12: 0107 | Q12: 01 | S12: 2
A13: 0108 지붕및홈통공사 | D13: 1 | E13: =공종별내역서!N217 -> 826112 | F13: =E13*D13 -> 826112 | G13: =공종별내역서!P217 -> 603568 | H13: =G13*D13 -> 603568 | I13: =공종별내역서!R217 -> 0 | J13: =I13*D13 -> 0 | K13: =E13+G13+I13 -> 1429680 | L13: =F13+H13+J13 -> 1429680 | M13: =+L13/$M$4 -> 885.37251 | O13: 0108 | Q13: 01 | S13: 2
A14: 0109 금 속 공 사 | D14: 1 | E14: =공종별내역서!N241 -> 46891105 | F14: =E14*D14 -> 46891105 | G14: =공종별내역서!P241 -> 9604267 | H14: =G14*D14 -> 9604267 | I14: =공종별내역서!R241 -> 171290 | J14: =I14*D14 -> 171290 | K14: =E14+G14+I14 -> 56666662 | L14: =F14+H14+J14 -> 56666662 | M14: =+L14/$M$4 -> 35092.542 | O14: 0109 | Q14: 01 | S14: 2
A15: 0110 미 장 공 사 | D15: 1 | E15: =공종별내역서!N265 -> 0 | F15: =E15*D15 -> 0 | G15: =공종별내역서!P265 -> 145914867 | H15: =G15*D15 -> 145914867 | I15: =공종별내역서!R265 -> 2569173 | J15: =I15*D15 -> 2569173 | K15: =E15+G15+I15 -> 148484040 | L15: =F15+H15+J15 -> 148484040 | M15: =+L15/$M$4 -> 91953.225 | O15: 0110 | Q15: 01 | S15: 2
A16: 0111 창 호 공 사 | D16: 1 | E16: =공종별내역서!N289 -> 494767669 | F16: =E16*D16 -> 494767669 | G16: =공종별내역서!P289 -> 13273282 | H16: =G16*D16 -> 13273282 | I16: =공종별내역서!R289 -> 363419 | J16: =I16*D16 -> 363419 | K16: =E16+G16+I16 -> 508404370 | L16: =F16+H16+J16 -> 508404370 | M16: =+L16/$M$4 -> 314844.76 | O16: 0111 | Q16: 01 | S16: 2
A17: 0112 유 리 공 사 | D17: 1 | E17: =공종별내역서!N313 -> 117928098 | F17: =E17*D17 -> 117928098 | G17: =공종별내역서!P313 -> 79937436 | H17: =G17*D17 -> 79937436 | I17: =공종별내역서!R313 -> 0 | J17: =I17*D17 -> 0 | K17: =E17+G17+I17 -> 197865534 | L17: =F17+H17+J17 -> 197865534 | M17: =+L17/$M$4 -> 122534.21 | O17: 0112 | Q17: 01 | S17: 2
A18: 0113 도 장 공 사 | D18: 1 | E18: =공종별내역서!N337 -> 64872320 | F18: =E18*D18 -> 64872320 | G18: =공종별내역서!P337 -> 136479888 | H18: =G18*D18 -> 136479888 | I18: =공종별내역서!R337 -> 672000 | J18: =I18*D18 -> 672000 | K18: =E18+G18+I18 -> 202024208 | L18: =F18+H18+J18 -> 202024208 | M18: =+L18/$M$4 -> 125109.59 | O18: 0113 | Q18: 01 | S18: 2
A19: 0114 수 장 공 사 | D19: 1 | E19: =공종별내역서!N360 -> 152117603 | F19: =E19*D19 -> 152117603 | G19: =공종별내역서!P360 -> 208830578 | H19: =G19*D19 -> 208830578 | I19: =공종별내역서!R360 -> 2346381 | J19: =I19*D19 -> 2346381 | K19: =E19+G19+I19 -> 363294562 | L19: =F19+H19+J19 -> 363294562 | M19: =+L19/$M$4 -> 224981.13 | O19: 0114 | Q19: 01 | S19: 2
A20: 0115 골재비 및 운반비 | D20: 1 | E20: =공종별내역서!N384 -> 19880057 | F20: =E20*D20 -> 19880057 | G20: =공종별내역서!P384 -> 0 | H20: =G20*D20 -> 0 | I20: =공종별내역서!R384 -> 4211920 | J20: =I20*D20 -> 4211920 | K20: =E20+G20+I20 -> 24091977 | L20: =F20+H20+J20 -> 24091977 | M20: =+L20/$M$4 -> 14919.684 | O20: 0115 | Q20: 01 | S20: 2
A27: [ 합 계 ] | F27: =F5 -> 2173427021 | H27: =H5 -> 2898047135 | J27: =J5 -> 102238233 | L27: =L5 -> 5173712389 | M27: =+L27/$M$4 -> 3203977.6

Sheet 공종별내역서
I1: [ 업무시설 ] | BF1: 지하층 | BH1: 지상층
A2: 대분류 | B2: 중분류 | C2: 소분류 | D2: 층분류 | E2: 주요실 | F2: 수식관련 | I2: 품 명 | J2: 규 격 | K2: 단위 | L2: 수량 | M2: 재 료 비 | O2: 노 무 비 | Q2: 경 비 | S2: 합 계 | U2: 비 고 | V2: 품목코드 | W2: 변수 | X2: 설정 | Y2: 공종코드 | Z2: 일위 | AA2: 단산 | AB2: 자재 | AC2: 손료적용 | AD2: 손료저장 | AE2: 적용율 | AF2: JUK1 | AG2: JUK2 | AH2: JUK3 | AI2: JUK4 | AJ2: JUK5 | AK2: JUK6 | AL2: JUK7 | AM2: JUK8 | AN2: JUK9 | AO2: JUK10 | AP2: JUK11 | AQ2: JUK12 | AR2: JUK13 | AS2: JUK14 | AT2: JUK15 | AU2: JUK16 | AV2: JUK17 | AW2: JUK18 | AX2: JUK19 | AY2: JUK20 | AZ2: 자재구분 | BA2: 공종구분 | BB2: 공종레벨 | BC2: 공종+자재 | BD2: 고유번호 | BF2: 최하층 | BG2: 기준층 | BH2: 1층 | BI2: 2층 | BJ2: 기준층 | BK2: 옥탑층
M3: 단 가 | N3: 금 액 | O3: 단 가 | P3: 금 액 | Q3: 단 가 | R3: 금 액 | S3: 단 가 | T3: 금 액
A4: =+I4 -> 0101 공통 가설 공사 | I4: 0101 공통 가설 공사 | Y4: 0101
A5: =+A4 -> 0101 공통 가설 공사 | B5: 가설 | C5: 공통가설 | F5: 대지면적 | I5: 조립식가설울타리/E.G.I철판 | J5: H=2.4, 12개월 | K5: M | L5: =ROUNDUP(개요!D3,0) -> 130 | M5: =TRUNC(일위대가목록!E4,0) -> 0 | N5: =TRUNC(M5*L5, 0) -> 0 | O5: =TRUNC(일위대가목록!F4,0) -> 0 | P5: =TRUNC(O5*L5, 0) -> 0 | Q5: =TRUNC(일위대가목록!G4,0) -> 54703 | R5: =TRUNC(Q5*L5, 0) -> 7111390 | S5: =TRUNC(M5+O5+Q5, 0) -> 54703 | T5: =TRUNC(N5+P5+R5, 0) -> 7111390 | V5: 5A16950BD57D4F7AF3F35FA769ECF0 | Y5: 0101 | Z5: T | AA5: F | AB5: F | BC5: 01015A16950BD57D4F7AF3F35FA769ECF0 | BD5: 3
A6: =+A5 -> 0101 공통 가설 공사 | B6: 가설 | C6: 공통가설 | F6: 고정 | I6: 가설게이트 | K6: EA | L6: 1 | M6: =TRUNC(일위대가목록!E5,0) -> 0 | N6: =TRUNC(M6*L6, 0) -> 0 | O6: =TRUNC(일위대가목록!F5,0) -> 0 | P6: =TRUNC(O6*L6, 0) -> 0 | Q6: =TRUNC(일위대가목록!G5,0) -> 15269645 | R6: =TRUNC(Q6*L6, 0) -> 15269645 | S6: =TRUNC(M6+O6+Q6, 0) -> 15269645 | T6: =TRUNC(N6+P6+R6, 0) -> 15269645 | V6: 5A16950EA97B5424F3CC512B39781F | Y6: 0101 | Z6: T | AA6: F | AB6: F | BC6: 01015A16950EA97B5424F3CC512B39781F | BD6: 4
A7: =+A6 -> 0101 공통 가설 공사 | B7: 가설 | C7: 공통가설 | F7: 연면적 | I7: 조립식가설사무소/감리, 감독자 | J7: 12개월 | K7: M2 | L7: =+INDEX(개요!$Y$2:$AA$5,MATCH(개요!D12,개요!X2:X5,-1),1) -> 46 | M7: =TRUNC(일위대가목록!E6,0) -> 0 | N7: =TRUNC(M7*L7, 0) -> 0 | O7: =TRUNC(일위대가목록!F6,0) -> 0 | P7: =TRUNC(O7*L7, 0) -> 0 | Q7: =TRUNC(일위대가목록!G6,0) -> 101535 | R7: =TRUNC(Q7*L7, 0) -> 4670610 | S7: =TRUNC(M7+O7+Q7, 0) -> 101535 | T7: =TRUNC(N7+P7+R7, 0) -> 4670610 | V7: 5A169508017B584A431B5C2C79C741 | Y7: 0101 | Z7: T | AA7: F | AB7: F | BC7: 01015A169508017B584A431B5C2C79C741 | BD7: 8
A8: =+A7 -> 0101 공통 가설 공사 | B8: 가설 | C8: 공통가설 | F8: 연면적 | I8: 조립식가설사무소/수급자 | J8: 12개월 | K8: M2 | L8: =+INDEX(개요!$Y$2:$AA$5,MATCH(개요!D12,개요!X2:X5,-1),2) -> 60 | M8: =TRUNC(일위대가목록!E7,0) -> 0 | N8: =TRUNC(M8*L8, 0) -> 0 | O8: =TRUNC(일위대가목록!F7,0) -> 0 | P8: =TRUNC(O8*L8, 0) -> 0 | Q8: =TRUNC(일위대가목록!G7,0) -> 101535 | R8: =TRUNC(Q8*L8, 0) -> 6092100 | S8: =TRUNC(M8+O8+Q8, 0) -> 101535 | T8: =TRUNC(N8+P8+R8, 0) -> 6092100 | V8: 5A169508017B584A431B5C2C79C740 | Y8: 0101 | Z8: T | AA8: F | AB8: F | BC8: 01015A169508017B584A431B5C2C79C740 | BD8: 9
A9: =+A8 -> 0101 공통 가설 공사 | B9: 가설 | C9: 공통가설 | F9: 연면적 | I9: 조립식가설창고 | J9: 12개월 | K9: M2 | L9: =+INDEX(개요!$Y$2:$AA$5,MATCH(개요!D12,개요!X2:X5,-1),3) -> 130 | M9: =TRUNC(일위대가목록!E8,0) -> 0 | N9: =TRUNC(M9*L9, 0) -> 0 | O9: =TRUNC(일위대가목록!F8,0) -> 0 | P9: =TRUNC(O9*L9, 0) -> 0 | Q9: =TRUNC(일위대가목록!G8,0) -> 76951 | R9: =TRUNC(Q9*L9, 0) -> 10003630 | S9: =TRUNC(M9+O9+Q9, 0) -> 76951 | T9: =TRUNC(N9+P9+R9, 0) -> 10003630 | V9: 5A169508017B6AB4D35654021934CC | Y9: 0101 | Z9: T | AA9: F | AB9: F | BC9: 01015A169508017B6AB4D35654021934CC | BD9: 10
A10: =+A9 -> 0101 공통 가설 공사
A11: =+A10 -> 0101 공통 가설 공사
A12: =+A11 -> 0101 공통 가설 공사
A13: =+A12 -> 0101 공통 가설 공사
A14: =+A13 -> 0101 공통 가설 공사
A15: =+A14 -> 0101 공통 가설 공사
A16: =+A15 -> 0101 공통 가설 공사
A17: =+A16 -> 0101 공통 가설 공사
A18: =+A17 -> 0101 공통 가설 공사
A19: =+A18 -> 0101 공통 가설 공사
A20: =+A19 -> 0101 공통 가설 공사
A21: =+A20 -> 0101 공통 가설 공사
... A26: =+A25 -> 0101 공통 가설 공사
A27: =+A26 -> 0101 공통 가설 공사 | I27: [ 합 계 ] | N27: =SUM(N5:N26) -> 0 | P27: =SUM(P5:P26) -> 0 | R27: =SUM(R5:R26) -> 43147375 | T27: =SUM(T5:T26) -> 43147375 | V27: TOTAL
A28: =+I28 -> 0102 가 설 공 사 | I28: 0102 가 설 공 사 | Y28: 0102
A29: =+A28 -> 0102 가 설 공 사 | B29: 가설 | C29: 직접가설 | F29: 건축면적 | I29: 면적당규준틀 | K29: M2 | L29: =ROUNDUP(개요!D4,0) -> 616 | M29: =TRUNC(일위대가목록!E9,0) -> 584 | N29: =TRUNC(M29*L29, 0) -> 359744 | O29: =TRUNC(일위대가목록!F9,0) -> 6145 | P29: =TRUNC(O29*L29, 0) -> 3785320 | Q29: =TRUNC(일위대가목록!G9,0) -> 0 | R29: =TRUNC(Q29*L29, 0) -> 0 | S29: =TRUNC(M29+O29+Q29, 0) -> 6729 | T29: =TRUNC(N29+P29+R29, 0) -> 4145064 | V29: 5A16950BD779EAC343BE5B2FB9F77F | Y29: 0102 | Z29: T | AA29: F | AB29: F | BC29: 01025A16950BD779EAC343BE5B2FB9F77F | BD29: 12
A30: =+A29 -> 0102 가 설 공 사 | B30: 가설 | C30: 직접가설 | I30: 강관동바리 설치 및 해체 | J30: 4.2m 이하 | K30: M2 | L30: =개요!D83 -> 1564.083 | M30: =TRUNC(일위대가목록!E10,0) -> 1453 | N30: =TRUNC(M30*L30, 0) -> 2272612 | O30: =TRUNC(일위대가목록!F10,0) -> 14638 | P30: =TRUNC(O30*L30, 0) -> 22895046 | Q30: =TRUNC(일위대가목록!G10,0) -> 0 | R30: =TRUNC(Q30*L30, 0) -> 0 | S30: =TRUNC(M30+O30+Q30, 0) -> 16091 | T30: =TRUNC(N30+P30+R30, 0) -> 25167658 | V30: 5A16950BD779D84053F8599D2962C7 | Y30: 0102 | Z30: T | AA30: F | AB30: F | BC30: 01025A16950BD779D84053F8599D2962C7 | BD30: 13
A31: =+A30 -> 0102 가 설 공 사 | B31: 가설 | C31: 직접가설 | I31: 시스템동바리 설치 및 해체 | J31: 10m 이하 | K31: 10공M3 | L31: =개요!E83 -> 1537.0248 | M31: =TRUNC(일위대가목록!E11,0) -> 64927 | N31: =TRUNC(M31*L31, 0) -> 99794409 | O31: =TRUNC(일위대가목록!F11,0) -> 160307 | P31: =TRUNC(O31*L31, 0) -> 246395835 | Q31: =TRUNC(일위대가목록!G11,0) -> 6406 | R31: =TRUNC(Q31*L31, 0) -> 9846180 | S31: =TRUNC(M31+O31+Q31, 0) -> 231640 | T31: =TRUNC(N31+P31+R31, 0) -> 356036424 | V31: 5A16950BD779D852C3825C3B09B571 | Y31: 0102 | Z31: T | AA31: F | AB31: F | BC31: 01025A16950BD779D852C3825C3B09B571 | BD31: 14
A32: =+A31 -> 0102 가 설 공 사 | B32: 가설 | C32: 직접가설 | F32: 둘레 | G32: 층고 | I32: 시스템비계 설치 및 해체 | K32: M2 | L32: =ROUNDUP(개요!D13*개요!E28/1000*개요!F28+개요!D13*개요!E29/1000*개요!F29+개요!D13*개요!E30/1000*개요!F30+개요!D15*개요!E31/1000*개요!F31,0) -> 4101 | M32: =TRUNC(일위대가목록!E12,0) -> 7821 | N32: =TRUNC(M32*L32, 0) -> 32073921 | O32: =TRUNC(일위대가목록!F12,0) -> 10864 | P32: =TRUNC(O32*L32, 0) -> 44553264 | Q32: =TRUNC(일위대가목록!G12,0) -> 0 | R32: =TRUNC(Q32*L32, 0) -> 0 | S32: =TRUNC(M32+O32+Q32, 0) -> 18685 | T32: =TRUNC(N32+P32+R32, 0) -> 76627185 | V32: 5A16950BD779EADDD394526749C7D3 | Y32: 0102 | Z32: T | AA32: F | AB32: F | BC32: 01025A16950BD779EADDD394526749C7D3 | BD32: 15
A33: =+A32 -> 0102 가 설 공 사 | B33: 가설 | C33: 직접가설 | F33: 옥탑층고 | I33: 가설 계단 설치 및 해체 | K33: M2 | L33: =ROUNDUP((개요!E31/1000/0.3*0.9)+(1.8*5.4)*개요!F31,0) -> 24 | M33: =TRUNC(일위대가목록!E13,0) -> 7190 | N33: =TRUNC(M33*L33, 0) -> 172560 | O33: =TRUNC(일위대가목록!F13,0) -> 76460 | P33: =TRUNC(O33*L33, 0) -> 1835040 | Q33: =TRUNC(일위대가목록!G13,0) -> 1529 | R33: =TRUNC(Q33*L33, 0) -> 36696 | S33: =TRUNC(M33+O33+Q33, 0) -> 85179 | T33: =TRUNC(N33+P33+R33, 0) -> 2044296 | V33: 5A16950BD779EADD8316588FA97414 | Y33: 0102 | Z33: T | AA33: F | AB33: F | BC33: 01025A16950BD779EADD8316588FA97414 | BD33: 16
A34: =+A33 -> 0102 가 설 공 사 | B34: 가설 | C34: 직접가설 | F34: 지상연면적 | I34: 이동식강관밀비계 | J34: 높이 2m, 3개월 | K34: 대 | L34: =ROUNDUP(개요!D11/200,0) -> 19 | M34: =TRUNC(일위대가목록!E14,0) -> 12912 | N34: =TRUNC(M34*L34, 0) -> 245328 | O34: =TRUNC(일위대가목록!F14,0) -> 78672 | P34: =TRUNC(O34*L34, 0) -> 1494768 | Q34: =TRUNC(일위대가목록!G14,0) -> 0 | R34: =TRUNC(Q34*L34, 0) -> 0 | S34: =TRUNC(M34+O34+Q34, 0) -> 91584 | T34: =TRUNC(N34+P34+R34, 0) -> 1740096 | V34: 5A16950BD779EADDF3475041699AEA | Y34: 0102 | Z34: T | AA34: F | AB34: F | BC34: 01025A16950BD779EADDF3475041699AEA | BD34: 17
A35: =+A34 -> 0102 가 설 공 사 | B35: 가설 | C35: 직접가설 | F35: 지하연면적 | I35: 이동식강관밀비계 | J35: 높이 4m, 3개월 | K35: 대 | L35: =ROUNDUP(개요!D10/200,0) -> 9 | M35: =TRUNC(일위대가목록!E15,0) -> 20066 | N35: =TRUNC(M35*L35, 0) -> 180594 | O35: =TRUNC(일위대가목록!F15,0) -> 130469 | P35: =TRUNC(O35*L35, 0) -> 1174221 | Q35: =TRUNC(일위대가목록!G15,0) -> 0 | R35: =TRUNC(Q35*L35, 0) -> 0 | S35: =TRUNC(M35+O35+Q35, 0) -> 150535 | T35: =TRUNC(N35+P35+R35, 0) -> 1354815 | V35: 5A16950BD779EADDF347507EA939BB | Y35: 0102 | Z35: T | AA35: F | AB35: F | BC35: 01025A16950BD779EADDF347507EA939BB | BD35: 18
A36: =+A35 -> 0102 가 설 공 사 | B36: 가설 | C36: 직접가설 | F36: 건축면적 | G36: 연면적 | I36: 건축물보양 - 콘크리트 | J36: 살수 | K36: M2 | L36: =ROUNDUP(개요!D4+개요!D12,0) -> 5954 | M36: =TRUNC(일위대가목록!E16,0) -> 0 | N36: =TRUNC(M36*L36, 0) -> 0 | O36: =TRUNC(일위대가목록!F16,0) -> 555 | P36: =TRUNC(O36*L36, 0) -> 3304470 | Q36: =TRUNC(일위대가목록!G16,0) -> 0 | R36: =TRUNC(Q36*L36, 0) -> 0 | S36: =TRUNC(M36+O36+Q36, 0) -> 555 | T36: =TRUNC(N36+P36+R36, 0) -> 3304470 | V36: 5A16950EAA75748B13245FC1B98935 | Y36: 0102 | Z36: T | AA36: F | AB36: F | BC36: 01025A16950EAA75748B13245FC1B98935 | BD36: 19
A37: =+A36 -> 0102 가 설 공 사 | B37: 가설 | C37: 직접가설 | F37: 연면적 | I37: 건축물보양 - 석재면, 테라조면 | J37: 하드롱지 | K37: M2 | L37: =ROUNDUP(940*개요!D12/개요!C12,0) -> 931 | M37: =TRUNC(일위대가목록!E17,0) -> 915 | N37: =TRUNC(M37*L37, 0) -> 851865 | O37: =TRUNC(일위대가목록!F17,0) -> 1389 | P37: =TRUNC(O37*L37, 0) -> 1293159 | Q37: =TRUNC(일위대가목록!G17,0) -> 0 | R37: =TRUNC(Q37*L37, 0) -> 0 | S37: =TRUNC(M37+O37+Q37, 0) -> 2304 | T37: =TRUNC(N37+P37+R37, 0) -> 2145024 | V37: 5A16950EAA75748B23CD5D55F9C53E | Y37: 0102 | Z37: T | AA37: F | AB37: F | BC37: 01025A16950EAA75748B23CD5D55F9C53E | BD37: 20
A38: =+A37 -> 0102 가 설 공 사 | B38: 가설 | C38: 직접가설 | F38: 연면적 | I38: 건축물보양 - 타일 | J38: 톱밥 | K38: M2 | L38: =ROUNDUP(186*개요!D12/개요!C12,0) -> 185 | M38: =TRUNC(일위대가목록!E18,0) -> 0 | N38: =TRUNC(M38*L38, 0) -> 0 | O38: =TRUNC(일위대가목록!F18,0) -> 277 | P38: =TRUNC(O38*L38, 0) -> 51245 | Q38: =TRUNC(일위대가목록!G18,0) -> 0 | R38: =TRUNC(Q38*L38, 0) -> 0 | S38: =TRUNC(M38+O38+Q38, 0) -> 277 | T38: =TRUNC(N38+P38+R38, 0) -> 51245 | V38: 5A16950EAA75748B23CC5CD4790B74 | Y38: 0102 | Z38: T | AA38: F | AB38: F | BC38: 01025A16950EAA75748B23CC5CD4790B74 | BD38: 21
A39: =+A38 -> 0102 가 설 공 사 | B39: 가설 | C39: 직접가설 | F39: 연면적 | I39: 건축물 현장정리 | J39: 철근콘크리트조 | K39: M2 | L39: =ROUNDUP(개요!D12,0) -> 5339 | M39: =TRUNC(일위대가목록!E19,0) -> 0 | N39: =TRUNC(M39*L39, 0) -> 0 | O39: =TRUNC(일위대가목록!F19,0) -> 20848 | P39: =TRUNC(O39*L39, 0) -> 111307472 | Q39: =TRUNC(일위대가목록!G19,0) -> 0 | R39: =TRUNC(Q39*L39, 0) -> 0 | S39: =TRUNC(M39+O39+Q39, 0) -> 20848 | T39: =TRUNC(N39+P39+R39, 0) -> 111307472 | V39: 5A16950EA97B70F3D33B542E498E23 | Y39: 0102 | Z39: T | AA39: F | AB39: F | BC39: 01025A16950EA97B70F3D33B542E498E23 | BD39: 22
A40: =+A39 -> 0102 가 설 공 사 | B40: 가설 | C40: 직접가설 | F40: 연면적 | I40: 먹매김 | K40: M2 | L40: =ROUNDUP(개요!D12,0) -> 5339 | M40: =TRUNC(일위대가목록!E20,0) -> 0 | N40: =TRUNC(M40*L40, 0) -> 0 | O40: =TRUNC(일위대가목록!F20,0) -> 3703 | P40: =TRUNC(O40*L40, 0) -> 19770317 | Q40: =TRUNC(일위대가목록!G20,0) -> 0 | R40: =TRUNC(Q40*L40, 0) -> 0 | S40: =TRUNC(M40+O40+Q40, 0) -> 3703 | T40: =TRUNC(N40+P40+R40, 0) -> 19770317 | V40: 5A16950EAA7574B0731B5A3A99F539 | Y40: 0102 | Z40: T | AA40: F | AB40: F | BC40: 01025A16950EAA7574B0731B5A3A99F539 | BD40: 23
A41: =+A40 -> 0102 가 설 공 사
A42: =+A41 -> 0102 가 설 공 사
A43: =+A42 -> 0102 가 설 공 사
A44: =+A43 -> 0102 가 설 공 사
...

Sheet 일위대가목록
A1: 일 위 대 가 목 록
A2: [ 업무시설 ]
A3: 코 드 | B3: 품 명 | C3: 규 격 | D3: 단위 | E3: 재 료 비 | F3: 노 무 비 | G3: 경 비 | H3: 합 계 | I3: 번 호 | J3: 비 고 | K3: 노임계수 | L3: 할증 | M3: 품셈개요 | N3: 장비일위
A4: 5A16950BD57D4F7AF3F35FA769ECF0 | B4: 조립식가설울타리/E.G.I철판 | C4: H=2.4, 12개월 | D4: M | E4: =일위대가!F17 -> 0 | F4: =일위대가!H17 -> 0 | G4: =일위대가!J17 -> 54703 | H4: =E4+F4+G4 -> 54703 | I4: 호표 1 | J4: 토목 2-3-2 | M4: 토목 2-3-2
A5: 5A16950EA97B5424F3CC512B39781F | B5: 가설게이트 | D5: EA | E5: =일위대가!F35 -> 0 | F5: =일위대가!H35 -> 0 | G5: =일위대가!J35 -> 15269645 | H5: =E5+F5+G5 -> 15269645 | I5: 호표 2
A6: 5A169508017B584A431B5C2C79C741 | B6: 조립식가설사무소/감리, 감독자 | C6: 12개월 | D6: M2 | E6: =일위대가!F56 -> 0 | F6: =일위대가!H56 -> 0 | G6: =일위대가!J56 -> 101535 | H6: =E6+F6+G6 -> 101535 | I6: 호표 3 | J6: 공통 2-3-1, 2-2-2.1 | M6: 공통 2-3-1, 2-2-2.1
A7: 5A169508017B584A431B5C2C79C740 | B7: 조립식가설사무소/수급자 | C7: 12개월 | D7: M2 | E7: =일위대가!F77 -> 0 | F7: =일위대가!H77 -> 0 | G7: =일위대가!J77 -> 101535 | H7: =E7+F7+G7 -> 101535 | I7: 호표 4 | J7: 공통 2-3-1, 2-2-2.1 | M7: 공통 2-3-1, 2-2-2.1
A8: 5A169508017B6AB4D35654021934CC | B8: 조립식가설창고 | C8: 12개월 | D8: M2 | E8: =일위대가!F94 -> 0 | F8: =일위대가!H94 -> 0 | G8: =일위대가!J94 -> 76951 | H8: =E8+F8+G8 -> 76951 | I8: 호표 5 | J8: 공통 2-3-1, 2-2-2.1 | M8: 공통 2-3-1, 2-2-2.1
A9: 5A16950BD779EAC343BE5B2FB9F77F | B9: 면적당규준틀 | D9: M2 | E9: =일위대가!F100 -> 584 | F9: =일위대가!H100 -> 6145 | G9: =일위대가!J100 -> 0 | H9: =E9+F9+G9 -> 6729 | I9: 호표 6 | J9: 토목 2-4-2.3 | M9: 토목 2-4-2.3
A10: 5A16950BD779D84053F8599D2962C7 | B10: 강관동바리 설치 및 해체 | C10: 4.2m 이하 | D10: M2 | E10: =일위대가!F105 -> 1453 | F10: =일위대가!H105 -> 14638 | G10: =일위대가!J105 -> 0 | H10: =E10+F10+G10 -> 16091 | I10: 호표 7
A11: 5A16950BD779D852C3825C3B09B571 | B11: 시스템동바리 설치 및 해체 | C11: 10m 이하 | D11: 10공M3 | E11: =일위대가!F112 -> 64927 | F11: =일위대가!H112 -> 160307 | G11: =일위대가!J112 -> 6406 | H11: =E11+F11+G11 -> 231640 | I11: 호표 8 | J11: 공통 2-6-3 | M11: 공통 2-6-3
A12: 5A16950BD779EADDD394526749C7D3 | B12: 시스템비계 설치 및 해체 | D12: M2 | E12: =일위대가!F118 -> 7821 | F12: =일위대가!H118 -> 10864 | G12: =일위대가!J118 -> 0 | H12: =E12+F12+G12 -> 18685 | I12: 호표 9 | J12: 공통 2-7-2 | M12: 공통 2-7-2
A13: 5A16950BD779EADD8316588FA97414 | B13: 가설 계단 설치 및 해체 | D13: M2 | E13: =일위대가!F125 -> 7190 | F13: =일위대가!H125 -> 76460 | G13: =일위대가!J125 -> 1529 | H13: =E13+F13+G13 -> 85179 | I13: 호표 10 | J13: 공통 2-7-5 | M13: 공통 2-7-5
A14: 5A16950BD779EADDF3475041699AEA | B14: 이동식강관밀비계 | C14: 높이 2m, 3개월 | D14: 대 | E14: =일위대가!F138 -> 12912 | F14: =일위대가!H138 -> 78672 | G14: =일위대가!J138 -> 0 | H14: =E14+F14+G14 -> 91584 | I14: 호표 11 | J14: 공통 2-7-4 | M14: 공통 2-7-4
A15: 5A16950BD779EADDF347507EA939BB | B15: 이동식강관밀비계 | C15: 높이 4m, 3개월 | D15: 대 | E15: =일위대가!F152 -> 20066 | F15: =일위대가!H152 -> 130469 | G15: =일위대가!J152 -> 0 | H15: =E15+F15+G15 -> 150535 | I15: 호표 12 | J15: 공통 2-7-4 | M15: 공통 2-7-4
A16: 5A16950EAA75748B13245FC1B98935 | B16: 건축물보양 - 콘크리트 | C16: 살수 | D16: M2 | E16: =일위대가!F156 -> 0 | F16: =일위대가!H156 -> 555 | G16: =일위대가!J156 -> 0 | H16: =E16+F16+G16 -> 555 | I16: 호표 13 | J16: 공통 2-9-1 | M16: 공통 2-9-1
A17: 5A16950EAA75748B23CD5D55F9C53E | B17: 건축물보양 - 석재면, 테라조면 | C17: 하드롱지 | D17: M2 | E17: =일위대가!F162 -> 915 | F17: =일위대가!H162 -> 1389 | G17: =일위대가!J162 -> 0 | H17: =E17+F17+G17 -> 2304 | I17: 호표 14 | J17: 공통 2-9-1 | M17: 공통 2-9-1
A18: 5A16950EAA75748B23CC5CD4790B74 | B18: 건축물보양 - 타일 | C18: 톱밥 | D18: M2 | E18: =일위대가!F167 -> 0 | F18: =일위대가!H167 -> 277 | G18: =일위대가!J167 -> 0 | H18: =E18+F18+G18 -> 277 | I18: 호표 15 | J18: 공통 2-9-1 | M18: 공통 2-9-1
A19: 5A16950EA97B70F3D33B542E498E23 | B19: 건축물 현장정리 | C19: 철근콘크리트조 | D19: M2 | E19: =일위대가!F171 -> 0 | F19: =일위대가!H171 -> 20848 | G19: =일위대가!J171 -> 0 | H19: =E19+F19+G19 -> 20848 | I19: 호표 16 | J19: 공통 2-9-2 | M19: 공통 2-9-2
A20: 5A16950EAA7574B0731B5A3A99F539 | B20: 먹매김 | D20: M2 | E20: =일위대가!F176 -> 0 | F20: =일위대가!H176 -> 3703 | G20: =일위대가!J176 -> 0 | H20: =E20+F20+G20 -> 3703 | I20: 호표 17
A21: 5A16C5B93075989E434A5675E97A91 | B21: 레미콘타설 | C21: 무근(미할증) | D21: M3 | E21: =일위대가!F181 -> 1167 | F21: =일위대가!H181 -> 13561 | G21: =일위대가!J181 -> 3217 | H21: =E21+F21+G21 -> 17945 | I21: 호표 18 | J21: 토목 6-1-2 | M21: 토목 6-1-2
A22: 5A16C5B93372E7369348576AD939D9 | B22: 레미콘타설 | C22: 철근(미할증) | D22: M3 | E22: =일위대가!F186 -> 910 | F22: =일위대가!H186 -> 14737 | G22: =일위대가!J186 -> 2508 | H22: =E22+F22+G22 -> 18155 | I22: 호표 19 | J22: 토목 6-1-2 | M22: 토목 6-1-2
A23: 5A16C5BDAC70830023F05D866910DB | B23: 철근현장가공 및 조립 | C23: 보통(미할증) | D23: TON | E23: =일위대가!F195 -> 7930 | F23: =일위대가!H195 -> 861206 | G23: =일위대가!J195 -> 6842 | H23: =E23+F23+G23 -> 875978 | I23: 호표 20 | J23: 공통 6-2-2 | M23: 공통 6-2-2
A24: 5A16C5BEB174C2D3334E5E6CC92F57 | B24: 합판거푸집 | C24: 3회 | D24: M2 | E24: =일위대가!F200 -> 10376 | F24: =일위대가!H200 -> 40888 | G24: =일위대가!J200 -> 408 | H24: =E24+F24+G24 -> 51672 | I24: 호표 21 | J24: 공통 6-3-1 | M24: 공통 6-3-1
A25: 5A16C5BEB174C2D3334F58DB699E38 | B25: 합판거푸집 | C25: 4회 | D25: M2 | E25: =일위대가!F205 -> 8983 | F25: =일위대가!H205 -> 28458 | G25: =일위대가!J205 -> 284 | H25: =E25+F25+G25 -> 37725 | I25: 호표 22 | J25: 공통 6-3-1 | M25: 공통 6-3-1
A26: 5A16C5BEB174D331C3675F3E19DFE7 | B26: 합판거푸집 | C26: 경사 3회 | D26: M2 | E26: =일위대가!F210 -> 10376 | F26: =일위대가!H210 -> 49066 | G26: =일위대가!J210 -> 408 | H26: =E26+F26+G26 -> 59850 | I26: 호표 23 | J26: 공통 6-3-1 | M26: 공통 6-3-1
A27: 5A16C5BEB1748B1C23AD50B01992EB | B27: 합판거푸집 | C27: 곡면 | D27: M2 | E27: =일위대가!F217 -> 18608 | F27: =일위대가!H217 -> 96701 | G27: =일위대가!J217 -> 0 | H27: =E27+F27+G27 -> 115309 | I27: 호표 24 | J27: 토목 6-3-3 | M27: 토목 6-3-3
A28: 5A16C5BEB77D5164938D59CFD98819 | B28: 유로폼 | C28: 벽 | D28: M2 | E28: =일위대가!F222 -> 2624 | F28: =일위대가!H222 -> 26250 | G28: =일위대가!J222 -> 787 | H28: =E28+F28+G28 -> 29661 | I28: 호표 25 | J28: 공통 6-3-3 | M28: 공통 6-3-3
A29: 5A16C5BEB77D515A03555784B9201C | B29: 합벽거푸집 | C29: 합벽 | D29: M2 | E29: =일위대가!F235 -> 15600 | F29: =일위대가!H235 -> 30735 | G29: =일위대가!J235 -> 0 | H29: =E29+F29+G29 -> 46335 | I29: 호표 26
A30: 5A16C5B700792AB403895A3999AD33 | B30: 지수판설치 - PVC 용접 | C30: PVC, H200*5t | D30: M | E30: =일위대가!F244 -> 3024 | F30: =일위대가!H244 -> 41479 | G30: =일위대가!J244 -> 1244 | H30: =E30+F30+G30 -> 45747 | I30: 호표 27 | J30: 공통 6-3-9.1 | M30: 공통 6-3-9.1
A31: 5A16B5598471B7F673115D0B190C79 | B31: 잡석지정 | C31: 굴삭기 0.2m3+진동롤러(핸드가이드식) | D31: M3 | E31: =일위대가!F249 -> 658 | F31: =일위대가!H249 -> 5445 | G31: =일위대가!J249 -> 1005 | H31: =E31+F31+G31 -> 7108 | I31: 호표 28 | J31: 공통 3-2-4 | M31: 공통 3-2-4
A32: 5A167539E672E7B9433C5EF6997A53 | B32: 방습필름 설치 - 바닥 | C32: 폴리에틸렌필름, 두께, 0.03mm, 2겹 | D32: M2 | E32: =일위대가!F254 -> 361 | F32: =일위대가!H254 -> 1172 | G32: =일위대가!J254 -> 0 | H32: =E32+F32+G32 -> 1533 | I32: 호표 29 | J32: 건축 5-3-3 | M32: 건축 5-3-3
A33: 5A16E58DEC749C4EE3CB56D339C036 | B33: 0.5B 벽돌쌓기 | C33: 3.6m 초과 | D33: M2 | E33: =일위대가!F262 -> 0 | F33: =일위대가!H262 -> 38167 | G33: =일위대가!J262 -> 728 | H33: =E33+F33+G33 -> 38895 | I33: 호표 30 | J33: 건축 2-1-1 | M33: 건축 2-1-1
A34: 5A16E58EF5766C4E336B5F07F9F61A | B34: 블록쌓기(390*190*190) | C34: 3.6m 초과, 양면마감 | D34: M2 | E34: =일위대가!F269 -> 0 | F34: =일위대가!H269 -> 47827 | G34: =일위대가!J269 -> 938 | H34: =E34+F34+G34 -> 48765 | I34: 호표 31 | J34: 건축 2-2-1 | M34: 건축 2-2-1
A35: 5A1655EDBD7D7D8C23255E3AB9A1A6 | B35: 화강석붙임(습식, 물갈기) | C35: 바닥, 포천석 30mm, 모르타르 70mm | D35: M2 | E35: =일위대가!F275 -> 56991 | F35: =일위대가!H275 -> 93596 | G35: =일위대가!J275 -> 871 | H35: =E35+F35+G35 -> 151458 | I35: 호표 32 | J35: 공통 7-4-1 | M35: 공통 7-4-1
A36: 5A1655EDBD7D7D8C23255E3AB9A1A5 | B36: 화강석붙임(습식, 물갈기) | C36: 바닥, 포천석 30mm, 모르타르 40mm | D36: M2 | E36: =일위대가!F281 -> 56991 | F36: =일위대가!H281 -> 90844 | G36: =일위대가!J281 -> 871 | H36: =E36+F36+G36 -> 148706 | I36: 호표 33 | J36: 공통 7-4-1 | M36: 공통 7-4-1
A37: 5A1655EDBD7D7D8C23255E3AB9A1A4 | B37: 화강석붙임(습식, 물갈기) | C37: 바닥, 포천석 30mm, 모르타르 20mm | D37: M2 | E37: =일위대가!F287 -> 56991 | F37: =일위대가!H287 -> 89009 | G37: =일위대가!J287 -> 871 | H37: =E37+F37+G37 -> 146871 | I37: 호표 34 | J37: 공통 7-4-1 | M37: 공통 7-4-1
A38: 5A1655EDBD7D7D8C23255E3AB9A1A3 | B38: 화강석붙임(습식, 물갈기) / 계단 | C38: 바닥, 포천석 30mm, 모르타르 20mm | D38: M2 | E38: =일위대가!F293 -> 56991 | F38: =일위대가!H293 -> 89009 | G38: =일위대가!J293 -> 871 | H38: =E38+F38+G38 -> 146871 | I38: 호표 35 | J38: 공통 7-4-1 | M38: 공통 7-4-1
A39: 5A1655EDBD7D7D8C23255E3AB9A1A2 | B39: 화강석붙임(습식, 물갈기) / 계단 | C39: 바닥, 포천석 30mm, 모르타르 40mm | D39: M2 | E39: =일위대가!F299 -> 56991 | F39: =일위대가!H299 -> 90844 | G39: =일위대가!J299 -> 871 | H39: =E39+F39+G39 -> 148706 | I39: 호표 36 | J39: 공통 7-4-1 | M39: 공통 7-4-1
A40: 5A1655EDBD7D404A43DF5EBEA95520 | B40: 화강석붙임(습식, 버너) / 주출입구 | C40: 바닥, 포천석 30mm, 모르타르 30mm | D40: M2 | E40: =일위대가!F305 -> 52635 | F40: =일위대가!H305 -> 89926 | G40: =일위대가!J305 -> 871 | H40: =E40+F40+G40 -> 143432 | I40: 호표 37 | J40: 공통 7-4-1 | M40: 공통 7-4-1
...

Sheet 일위대가
A1: [ 업무시설 ]
A2: 품 명 | B2: 규 격 | C2: 단위 | D2: 수량 | E2: 재 료 비 | G2: 노 무 비 | I2: 경 비 | K2: 합 계 | M2: 비 고 | N2: 일위대가 | O2: 품목코드 | P2: 일위 | Q2: 단산 | R2: 자재 | S2: 손료적용 | T2: 손료저장 | U2: 적용율 | V2: JUK1 | W2: JUK2 | X2: JUK3 | Y2: JUK4 | Z2: JUK5 | AA2: JUK6 | AB2: JUK7 | AC2: JUK8 | AD2: JUK9 | AE2: JUK10 | AF2: JUK11 | AG2: JUK12 | AH2: JUK13 | AI2: JUK14 | AJ2: JUK15 | AK2: JUK16 | AL2: JUK17 | AM2: JUK18 | AN2: JUK19 | AO2: JUK20 | AP2: 할증적용 | AQ2: 할증저장 | AR2: 할증율 | AS2: HAL1 | AT2: HAL2 | AU2: HAL3 | AV2: 자재구분 | AW2: 일위대가+자재 | AX2: 장비일위 | AY2: 설정
E3: 단 가 | F3: 금 액 | G3: 단 가 | H3: 금 액 | I3: 단 가 | J3: 금 액 | K3: 단 가 | L3: 금 액
A4: 조립식가설울타리/E.G.I철판 H=2.4, 12개월 M 토목 2-3-2 ( 호표 1 ) | N4: 5A16950BD57D4F7AF3F35FA769ECF0
A5: 조립식 가설울타리 부재 | B5: EGI철판, 550*2400 | C5: 매 | D5: 0.76 | E5: =단가대비표!O138 -> 11280 | F5: =TRUNC(E5*D5,1) -> 8572.8 | G5: =단가대비표!P138 -> 0 | H5: =TRUNC(G5*D5,1) -> 0 | I5: =단가대비표!V138 -> 0 | J5: =TRUNC(I5*D5,1) -> 0 | K5: =TRUNC(E5+G5+I5,1) -> 11280 | L5: =TRUNC(F5+H5+J5,1) -> 8572.8 | M5: 금액제외 | O5: 5D30A596ED736D7F939255D38920A14BB0625E | P5: F | Q5: F | R5: T | X5: 3 | AW5: 5A16950BD57D4F7AF3F35FA769ECF05D30A596ED736D7F939255D38920A14BB0625E | AY5: -
A6: 강관비계 | B6: 강관비계, 비계파이프, 48.6*2.3mm | C6: M | D6: 1.254 | E6: =단가대비표!O122 -> 2666.66 | F6: =TRUNC(E6*D6,1) -> 3343.9 | G6: =단가대비표!P122 -> 0 | H6: =TRUNC(G6*D6,1) -> 0 | I6: =단가대비표!V122 -> 0 | J6: =TRUNC(I6*D6,1) -> 0 | K6: =TRUNC(E6+G6+I6,1) -> 2666.6 | L6: =TRUNC(F6+H6+J6,1) -> 3343.9 | M6: 금액제외 | O6: 5D30A596ED736D42436D501189170AE98EA34D | P6: F | Q6: F | R6: T | X6: 3 | AW6: 5A16950BD57D4F7AF3F35FA769ECF05D30A596ED736D42436D501189170AE98EA34D | AY6: -
A7: 강관비계 부속철물 | B7: 클램프 고정,자동 | C7: 개 | D7: 0.4826 | E7: =단가대비표!O127 -> 1200 | F7: =TRUNC(E7*D7,1) -> 579.1 | G7: =단가대비표!P127 -> 0 | H7: =TRUNC(G7*D7,1) -> 0 | I7: =단가대비표!V127 -> 0 | J7: =TRUNC(I7*D7,1) -> 0 | K7: =TRUNC(E7+G7+I7,1) -> 1200 | L7: =TRUNC(F7+H7+J7,1) -> 579.1 | M7: 금액제외 | O7: 5D30A596ED736D42436D501189170AE98F4A3F | P7: F | Q7: F | R7: T | X7: 3 | AW7: 5A16950BD57D4F7AF3F35FA769ECF05D30A596ED736D42436D501189170AE98F4A3F | AY7: -
A8: 강관비계 부속철물 | B8: 이음철물, 연결핀 | C8: 개 | D8: 0.1064 | E8: =단가대비표!O123 -> 873 | F8: =TRUNC(E8*D8,1) -> 92.8 | G8: =단가대비표!P123 -> 0 | H8: =TRUNC(G8*D8,1) -> 0 | I8: =단가대비표!V123 -> 0 | J8: =TRUNC(I8*D8,1) -> 0 | K8: =TRUNC(E8+G8+I8,1) -> 873 | L8: =TRUNC(F8+H8+J8,1) -> 92.8 | M8: 금액제외 | O8: 5D30A596ED736D42436D501189170AE98F4A38 | P8: F | Q8: F | R8: T | X8: 3 | AW8: 5A16950BD57D4F7AF3F35FA769ECF05D30A596ED736D42436D501189170AE98F4A38 | AY8: -
A9: 조립식 가설울타리 부재 | B9: 볼트/넛트 | C9: 개 | D9: 2.5327 | E9: =단가대비표!O140 -> 508 | F9: =TRUNC(E9*D9,1) -> 1286.6 | G9: =단가대비표!P140 -> 0 | H9: =TRUNC(G9*D9,1) -> 0 | I9: =단가대비표!V140 -> 0 | J9: =TRUNC(I9*D9,1) -> 0 | K9: =TRUNC(E9+G9+I9,1) -> 508 | L9: =TRUNC(F9+H9+J9,1) -> 1286.6 | M9: 금액제외 | O9: 5D30A596ED736D7F939255D38920A14BB0663B | P9: F | Q9: F | R9: T | X9: 3 | AW9: 5A16950BD57D4F7AF3F35FA769ECF05D30A596ED736D7F939255D38920A14BB0663B | AY9: -
A10: CONC인력비빔타설 / 가설 - 17년 1분기 삭제 | B10: 무근울타리기초 | C10: M3 | D10: 0.038 | E10: =일위대가목록!E126 -> 0 | F10: =TRUNC(E10*D10,1) -> 0 | G10: =일위대가목록!F126 -> 0 | H10: =TRUNC(G10*D10,1) -> 0 | I10: =일위대가목록!G126 -> 526533 | J10: =TRUNC(I10*D10,1) -> 20008.2 | K10: =TRUNC(E10+G10+I10,1) -> 526533 | L10: =TRUNC(F10+H10+J10,1) -> 20008.2 | M10: 금액제외 | O10: 5A16950802752032A3625FDB29CF77 | P10: T | Q10: F | R10: F | X10: 3 | AW10: 5A16950BD57D4F7AF3F35FA769ECF05A16950802752032A3625FDB29CF77 | AY10: -
A11: 비계공 | B11: 일반공사 직종 | C11: 인 | D11: 0.04 | E11: =단가대비표!O235 -> 0 | F11: =TRUNC(E11*D11,1) -> 0 | G11: =단가대비표!P235 -> 236858 | H11: =TRUNC(G11*D11,1) -> 9474.3 | I11: =단가대비표!V235 -> 0 | J11: =TRUNC(I11*D11,1) -> 0 | K11: =TRUNC(E11+G11+I11,1) -> 236858 | L11: =TRUNC(F11+H11+J11,1) -> 9474.3 | M11: 금액제외 | O11: 5AC235BE0A707BF6C349567599F97ED497CF73 | P11: F | Q11: F | R11: T | V11: 1 | W11: 2 | X11: 3 | AW11: 5A16950BD57D4F7AF3F35FA769ECF05AC235BE0A707BF6C349567599F97ED497CF73 | AY11: -
A12: 보통인부 | B12: 일반공사 직종 | C12: 인 | D12: 0.02 | E12: =단가대비표!O233 -> 0 | F12: =TRUNC(E12*D12,1) -> 0 | G12: =단가대비표!P233 -> 138989 | H12: =TRUNC(G12*D12,1) -> 2779.7 | I12: =단가대비표!V233 -> 0 | J12: =TRUNC(I12*D12,1) -> 0 | K12: =TRUNC(E12+G12+I12,1) -> 138989 | L12: =TRUNC(F12+H12+J12,1) -> 2779.7 | M12: 금액제외 | O12: 5AC235BE0A707BF6C349567599F97ED497CF77 | P12: F | Q12: F | R12: T | V12: 1 | W12: 2 | X12: 3 | AW12: 5A16950BD57D4F7AF3F35FA769ECF05AC235BE0A707BF6C349567599F97ED497CF77 | AY12: -
A13: 공구손료 | B13: 인력품의 5% | C13: 식 | D13: 1 | E13: =TRUNC(SUMIF(V5:V16, RIGHTB(O13, 1), H5:H16)*U13, 2) -> 612.7 | F13: =TRUNC(E13*D13,1) -> 612.7 | G13: 0 | H13: =TRUNC(G13*D13,1) -> 0 | I13: 0 | J13: =TRUNC(I13*D13,1) -> 0 | K13: =TRUNC(E13+G13+I13,1) -> 612.7 | L13: =TRUNC(F13+H13+J13,1) -> 612.7 | M13: 금액제외 | O13: 5B0FE5AE7477F3C133A45DE3096D001 | P13: F | Q13: F | R13: F | S13: 1 | T13: 0 | U13: 0.05 | X13: 3 | AW13: 5A16950BD57D4F7AF3F35FA769ECF05B0FE5AE7477F3C133A45DE3096D001 | AY13: -
A14: 굴삭기(무한궤도) | B14: 0.2㎥ | C14: HR | D14: 0.05 | E14: =일위대가목록!E127 -> 6255 | F14: =TRUNC(E14*D14,1) -> 312.7 | G14: =일위대가목록!F127 -> 42474 | H14: =TRUNC(G14*D14,1) -> 2123.7 | I14: =일위대가목록!G127 -> 12301 | J14: =TRUNC(I14*D14,1) -> 615 | K14: =TRUNC(E14+G14+I14,1) -> 61030 | L14: =TRUNC(F14+H14+J14,1) -> 3051.4 | M14: 금액제외 | O14: 5D0B55B1397E340AE3CF5B03B99D8261B1EE9F3A | P14: T | Q14: F | R14: F | X14: 3 | AW14: 5A16950BD57D4F7AF3F35FA769ECF05D0B55B1397E340AE3CF5B03B99D8261B1EE9F3A | AY14: -
A15: 해체 | B15: 설치품의 40% | C15: 식 | D15: 1 | E15: 0 | F15: =TRUNC(E15*D15,1) -> 0 | G15: =TRUNC(SUMIF(W5:W16, RIGHTB(O15, 1), H5:H16)*U15, 2) -> 4901.6 | H15: =TRUNC(G15*D15,1) -> 4901.6 | I15: 0 | J15: =TRUNC(I15*D15,1) -> 0 | K15: =TRUNC(E15+G15+I15,1) -> 4901.6 | L15: =TRUNC(F15+H15+J15,1) -> 4901.6 | M15: 금액제외 | O15: 5B0FE5AE7477F3C133A45DE3096E002 | P15: F | Q15: F | R15: F | S15: 1 | T15: 1 | U15: 0.4 | X15: 3 | AW15: 5A16950BD57D4F7AF3F35FA769ECF05B0FE5AE7477F3C133A45DE3096E002 | AY15: -
A16: 경비로 적용 | B16: 합계의 100% | C16: 식 | D16: 1 | E16: 0 | F16: =TRUNC(E16*D16,1) -> 0 | G16: 0 | H16: =TRUNC(G16*D16,1) -> 0 | I16: =TRUNC(SUMIF(X5:X16, RIGHTB(O16, 1), L5:L16)*U16, 2) -> 54703.1 | J16: =TRUNC(I16*D16,1) -> 54703.1 | K16: =TRUNC(E16+G16+I16,1) -> 54703.1 | L16: =TRUNC(F16+H16+J16,1) -> 54703.1 | N16: 5A16950BD57D4F7AF3F35FA769ECF0 | O16: 5B0FE5AE7477F3C133A45DE3096F003 | P16: F | Q16: F | R16: F | S16: 3 | T16: 2 | U16: 1 | AW16: 5A16950BD57D4F7AF3F35FA769ECF05B0FE5AE7477F3C133A45DE3096E002
A17: [ 합 계 ] | F17: =TRUNC(SUMIF(N5:N16, N4, F5:F16),0) -> 0 | H17: =TRUNC(SUMIF(N5:N16, N4, H5:H16),0) -> 0 | J17: =TRUNC(SUMIF(N5:N16, N4, J5:J16),0) -> 54703 | L17: =F17+H17+J17 -> 54703 | N17: TOTAL | O17: TOTAL
A19: 가설게이트 EA ( 호표 2 ) | N19: 5A16950EA97B5424F3CC512B39781F
A20: 일반구조용각형강관 | B20: 일반구조용각형강관, 각형강관, 50*30*1.6mm | C20: M | D20: 135.744 | E20: =단가대비표!O220 -> 1495 | F20: =TRUNC(E20*D20,1) -> 202937.2 | G20: =단가대비표!P220 -> 0 | H20: =TRUNC(G20*D20,1) -> 0 | I20: =단가대비표!V220 -> 0 | J20: =TRUNC(I20*D20,1) -> 0 | K20: =TRUNC(E20+G20+I20,1) -> 1495 | L20: =TRUNC(F20+H20+J20,1) -> 202937.2 | M20: 금액제외 | O20: 5D4105E3FB7367AFC33F549059F2BDC6620103 | P20: F | Q20: F | R20: T | V20: 1 | AW20: 5A16950EA97B5424F3CC512B39781F5D4105E3FB7367AFC33F549059F2BDC6620103 | AY20: -
A21: 조립식 가설울타리 부재 | B21: EGI철판, 550*2400 | C21: M2 | D21: 24 | E21: =단가대비표!O139 -> 9000 | F21: =TRUNC(E21*D21,1) -> 216000 | G21: =단가대비표!P139 -> 0 | H21: =TRUNC(G21*D21,1) -> 0 | I21: =단가대비표!V139 -> 0 | J21: =TRUNC(I21*D21,1) -> 0 | K21: =TRUNC(E21+G21+I21,1) -> 9000 | L21: =TRUNC(F21+H21+J21,1) -> 216000 | M21: 금액제외 | O21: 5D30A596ED736D7F939255D38920A14BB0625D | P21: F | Q21: F | R21: T | V21: 1 | AW21: 5A16950EA97B5424F3CC512B39781F5D30A596ED736D7F939255D38920A14BB0625D | AY21: -
A22: 일반구조용각형강관 | B22: 일반구조용각형강관, 각형강관, 100*50*2.3mm | C22: M | D22: 20.54 | E22: =단가대비표!O221 -> 3884 | F22: =TRUNC(E22*D22,1) -> 79777.3 | G22: =단가대비표!P221 -> 0 | H22: =TRUNC(G22*D22,1) -> 0 | I22: =단가대비표!V221 -> 0 | J22: =TRUNC(I22*D22,1) -> 0 | K22: =TRUNC(E22+G22+I22,1) -> 3884 | L22: =TRUNC(F22+H22+J22,1) -> 79777.3 | M22: 금액제외 | O22: 5D4105E3FB7367AFC33F549059F2BDC663127A | P22: F | Q22: F | R22: T | V22: 1 | AW22: 5A16950EA97B5424F3CC512B39781F5D4105E3FB7367AFC33F549059F2BDC663127A | AY22: -
A23: 일반구조용각형강관 | B23: 일반구조용각형강관, 각형강관, 100*100*2.3mm | C23: M | D23: 17.92 | E23: =단가대비표!O219 -> 5256 | F23: =TRUNC(E23*D23,1) -> 94187.5 | G23: =단가대비표!P219 -> 0 | H23: =TRUNC(G23*D23,1) -> 0 | I23: =단가대비표!V219 -> 0 | J23: =TRUNC(I23*D23,1) -> 0 | K23: =TRUNC(E23+G23+I23,1) -> 5256 | L23: =TRUNC(F23+H23+J23,1) -> 94187.5 | M23: 금액제외 | O23: 5D4105E3FB7367AFC33F549059F2BDC6620A65 | P23: F | Q23: F | R23: T | V23: 1 | AW23: 5A16950EA97B5424F3CC512B39781F5D4105E3FB7367AFC33F549059F2BDC6620A65 | AY23: -
A24: 경량형강 | B24: 경량형강, 칼라C형강, 100*50*20, t3.2 | C24: TON | D24: 0.0308 | E24: =단가대비표!O47 -> 603000 | F24: =TRUNC(E24*D24,1) -> 18572.4 | G24: =단가대비표!P47 -> 0 | H24: =TRUNC(G24*D24,1) -> 0 | I24: =단가대비표!V47 -> 0 | J24: =TRUNC(I24*D24,1) -> 0 | K24: =TRUNC(E24+G24+I24,1) -> 603000 | L24: =TRUNC(F24+H24+J24,1) -> 18572.4 | M24: 금액제외 | O24: 5D30A596E47DBF41331850FF69C85AB13A893D | P24: F | Q24: F | R24: T | V24: 1 | AW24: 5A16950EA97B5424F3CC512B39781F5D30A596E47DBF41331850FF69C85AB13A893D | AY24: -
A25: 일반구조용압연강판 | B25: 일반구조용압연강판, 9.0mm | C25: TON | D25: 16.91 | E25: =단가대비표!O52 -> 678192 | F25: =TRUNC(E25*D25,1) -> 11468227 | G25: =단가대비표!P52 -> 0 | H25: =TRUNC(G25*D25,1) -> 0 | I25: =단가대비표!V52 -> 0 | J25: =TRUNC(I25*D25,1) -> 0 | K25: =TRUNC(E25+G25+I25,1) -> 678192 | L25: =TRUNC(F25+H25+J25,1) -> 11468227 | M25: 금액제외 | O25: 5D30A596E47D83DD93B9541CB9F1154C197B04 | P25: F | Q25: F | R25: T | V25: 1 | AW25: 5A16950EA97B5424F3CC512B39781F5D30A596E47D83DD93B9541CB9F1154C197B04 | AY25: -
A26: 앵커볼트 | B26: 앵커볼트, M19*600mm | C26: 개 | D26: 4.266 | E26: =단가대비표!O184 -> 1798 | F26: =TRUNC(E26*D26,1) -> 7670.2 | G26: =단가대비표!P184 -> 0 | H26: =TRUNC(G26*D26,1) -> 0 | I26: =단가대비표!V184 -> 0 | J26: =TRUNC(I26*D26,1) -> 0 | K26: =TRUNC(E26+G26+I26,1) -> 1798 | L26: =TRUNC(F26+H26+J26,1) -> 7670.2 | M26: 금액제외 | O26: 5D30B5BCE1728BD9333453A299C328865C1223 | P26: F | Q26: F | R26: T | V26: 1 | AW26: 5A16950EA97B5424F3CC512B39781F5D30B5BCE1728BD9333453A299C328865C1223 | AY26: -
A27: 상부롤러 | C27: EA | D27: 5.33 | E27: =단가대비표!O185 -> 0 | F27: =TRUNC(E27*D27,1) -> 0 | G27: =단가대비표!P185 -> 0 | H27: =TRUNC(G27*D27,1) -> 0 | I27: =단가대비표!V185 -> 30000 | J27: =TRUNC(I27*D27,1) -> 159900 | K27: =TRUNC(E27+G27+I27,1) -> 30000 | L27: =TRUNC(F27+H27+J27,1) -> 159900 | M27: 금액제외 | O27: 5D30B5BCE1728BD9232D5C53D983993C8BA02D | P27: F | Q27: F | R27: T | V27: 1 | AW27: 5A16950EA97B5424F3CC512B39781F5D30B5BCE1728BD9232D5C53D983993C8BA02D | AY27: -
A28: CONC인력비빔타설 / 가설 - 17년 1분기 삭제 | B28: 무근울타리기초 | C28: M3 | D28: 0.8 | E28: =일위대가목록!E126 -> 0 | F28: =TRUNC(E28*D28,1) -> 0 | G28: =일위대가목록!F126 -> 0 | H28: =TRUNC(G28*D28,1) -> 0 | I28: =일위대가목록!G126 -> 526533 | J28: =TRUNC(I28*D28,1) -> 421226.4 | K28: =TRUNC(E28+G28+I28,1) -> 526533 | L28: =TRUNC(F28+H28+J28,1) -> 421226.4 | M28: 금액제외 | O28: 5A16950802752032A3625FDB29CF77 | P28: T | Q28: F | R28: F | V28: 1 | AW28: 5A16950EA97B5424F3CC512B39781F5A16950802752032A3625FDB29CF77 | AY28: -
A29: 합판거푸집 | B29: 4회 | C29: M2 | D29: 5.2 | E29: =일위대가목록!E25 -> 8983 | F29: =TRUNC(E29*D29,1) -> 46711.6 | G29: =일위대가목록!F25 -> 28458 | H29: =TRUNC(G29*D29,1) -> 147981.6 | I29: =일위대가목록!G25 -> 284 | J29: =TRUNC(I29*D29,1) -> 1476.8 | K29: =TRUNC(E29+G29+I29,1) -> 37725 | L29: =TRUNC(F29+H29+J29,1) -> 196170 | M29: 금액제외 | O29: 5A16C5BEB174C2D3334F58DB699E38 | P29: T | Q29: F | R29: F | V29: 1 | AW29: 5A16950EA97B5424F3CC512B39781F5A16C5BEB174C2D3334F58DB699E38 | AY29: -
A30: 녹막이페인트 붓칠 | B30: 철재면, 1회, 1종 | C30: M2 | D30: 0.816 | E30: =일위대가목록!E112 -> 795 | F30: =TRUNC(E30*D30,1) -> 648.7 | G30: =일위대가목록!F112 -> 3422 | H30: =TRUNC(G30*D30,1) -> 2792.3 | I30: =일위대가목록!G112 -> 0 | J30: =TRUNC(I30*D30,1) -> 0 | K30: =TRUNC(E30+G30+I30,1) -> 4217 | L30: =TRUNC(F30+H30+J30,1) -> 3441 | M30: 금액제외 | O30: 5A1665D74C768586130F5C2429BDB6 | P30: T | Q30: F | R30: F | V30: 1 | AW30: 5A16950EA97B5424F3CC512B39781F5A1665D74C768586130F5C2429BDB6 | AY30: -
A31: 유성페인트 붓칠 | B31: 철재면, 2회. 1급 | C31: M2 | D31: 0.408 | E31: =일위대가목록!E113 -> 900 | F31: =TRUNC(E31*D31,1) -> 367.2 | G31: =일위대가목록!F113 -> 9127 | H31: =TRUNC(G31*D31,1) -> 3723.8 | I31: =일위대가목록!G113 -> 0 | J31: =TRUNC(I31*D31,1) -> 0 | K31: =TRUNC(E31+G31+I31,1) -> 10027 | L31: =TRUNC(F31+H31+J31,1) -> 4091 | M31: 금액제외 | O31: 5A1665D4F97CE8FC33BA55DFF97870 | P31: T | Q31: F | R31: F | V31: 1 | AW31: 5A16950EA97B5424F3CC512B39781F5A1665D4F97CE8FC33BA55DFF97870 | AY31: -
A32: 특별인부 | B32: 일반공사 직종 | C32: 인 | D32: 6 | E32: =단가대비표!O234 -> 0 | F32: =TRUNC(E32*D32,1) -> 0 | G32: =단가대비표!P234 -> 167926 | H32: =TRUNC(G32*D32,1) -> 1007556 | I32: =단가대비표!V234 -> 0 | J32: =TRUNC(I32*D32,1) -> 0 | K32: =TRUNC(E32+G32+I32,1) -> 167926 | L32: =TRUNC(F32+H32+J32,1) -> 1007556 | M32: 금액제외 | O32: 5AC235BE0A707BF6C349567599F97ED497CF76 | P32: F | Q32: F | R32: T | V32: 1 | AW32: 5A16950EA97B5424F3CC512B39781F5AC235BE0A707BF6C349567599F97ED497CF76 | AY32: -
A33: 보통인부 | B33: 일반공사 직종 | C33: 인 | D33: 10 | E33: =단가대비표!O233 -> 0 | F33: =TRUNC(E33*D33,1) -> 0 | G33: =단가대비표!P233 -> 138989 | H33: =TRUNC(G33*D33,1) -> 1389890 | I33: =단가대비표!V233 -> 0 | J33: =TRUNC(I33*D33,1) -> 0 | K33: =TRUNC(E33+G33+I33,1) -> 138989 | L33: =TRUNC(F33+H33+J33,1) -> 1389890 | M33: 금액제외 | O33: 5AC235BE0A707BF6C349567599F97ED497CF77 | P33: F | Q33: F | R33: T | V33: 1 | AW33: 5A16950EA97B5424F3CC512B39781F5AC235BE0A707BF6C349567599F97ED497CF77 | AY33: -
A34: 경비로적용 | B34: 합계의 100% | C34: 식 | D34: 1 | E34: 0 | F34: =TRUNC(E34*D34,1) -> 0 | G34: 0 | H34: =TRUNC(G34*D34,1) -> 0 | I34: =TRUNC(SUMIF(V20:V34, RIGHTB(O34, 1), L20:L34)*U34, 2) -> 15269646 | J34: =TRUNC(I34*D34,1) -> 15269646 | K34: =TRUNC(E34+G34+I34,1) -> 15269646 | L34: =TRUNC(F34+H34+J34,1) -> 15269646 | N34: 5A16950EA97B5424F3CC512B39781F | O34: 5B0FE5AE7477F3C133A45DE3096D001 | P34: F | Q34: F | R34: F | S34: 3 | T34: 2 | U34: 1 | AW34: 5A16950EA97B5424F3CC512B39781F5B0FE5AE7477F3C133A45DE3096D001
A35: [ 합 계 ] | F35: =TRUNC(SUMIF(N20:N34, N19, F20:F34),0) -> 0 | H35: =TRUNC(SUMIF(N20:N34, N19, H20:H34),0) -> 0 | J35: =TRUNC(SUMIF(N20:N34, N19, J20:J34),0) -> 15269645 | L35: =F35+H35+J35 -> 15269645 | N35: TOTAL | O35: TOTAL
A37: 조립식가설사무소/감리, 감독자 12개월 M2 공통 2-3-1, 2-2-2.1 ( 호표 3 ) | N37: 5A169508017B584A431B5C2C79C741
A38: 조립식건물부재 | B38: 조립식건물부재, BASE CHANNEL, 2.0mm이상 | C38: M | D38: 0.11 | E38: =단가대비표!O167 -> 3060 | F38: =TRUNC(E38*D38,1) -> 336.6 | G38: =단가대비표!P167 -> 0 | H38: =TRUNC(G38*D38,1) -> 0 | I38: =단가대비표!V167 -> 0 | J38: =TRUNC(I38*D38,1) -> 0 | K38: =TRUNC(E38+G38+I38,1) -> 3060 | L38: =TRUNC(F38+H38+J38,1) -> 336.6 | M38: 금액제외 | O38: 5D30A595DD7E93B1A3D65630D9A2FBA994D05F | P38: F | Q38: F | R38: T | V38: 1 | W38: 2 | AW38: 5A169508017B584A431B5C2C79C7415D30A595DD7E93B1A3D65630D9A2FBA994D05F | AY38: -
A39: 조립식건물부재 | B39: 조립식건물부재, TOP CHANEL, 2.0mm이상 | C39: M | D39: 0.11 | E39: =단가대비표!O168 -> 2783 | F39: =TRUNC(E39*D39,1) -> 306.1 | G39: =단가대비표!P168 -> 0 | H39: =TRUNC(G39*D39,1) -> 0 | I39: =단가대비표!V168 -> 0 | J39: =TRUNC(I39*D39,1) -> 0 | K39: =TRUNC(E39+G39+I39,1) -> 2783 | L39: =TRUNC(F39+H39+J39,1) -> 306.1 | M39: 금액제외 | O39: 5D30A595DD7E93B1A3D65630D9A2FBA994D05C | P39: F | Q39: F | R39: T | V39: 1 | W39: 2 | AW39: 5A169508017B584A431B5C2C79C7415D30A595DD7E93B1A3D65630D9A2FBA994D05C | AY39: -
A40: 조립식건물부재 | B40: 조립식건물부재, 외부판넬, 벽, 1.2*2.4m | C40: 매 | D40: 0.05 | E40: =단가대비표!O169 -> 39120 | F40: =TRUNC(E40*D40,1) -> 1956 | G40: =단가대비표!P169 -> 0 | H40: =TRUNC(G40*D40,1) -> 0 | I40: =단가대비표!V169 -> 0 | J40: =TRUNC(I40*D40,1) -> 0 | K40: =TRUNC(E40+G40+I40,1) -> 39120 | L40: =TRUNC(F40+H40+J40,1) -> 1956 | M40: 금액제외 | O40: 5D30A595DD7E93B1A3D65630D9A2FBA994D05D | P40: F | Q40: F | R40: T | V40: 1 | W40: 2 | AW40: 5A169508017B584A431B5C2C79C7415D30A595DD7E93B1A3D65630D9A2FBA994D05D | AY40: -
